Workbook

Sheet Хср персы
B1: путь | C1: редкость | D1: тип | E1: возвышение | F1: колво | G1: материал босса | H1: материал возвышения | I1: материал следа | J1: босс следа | K1: талант | L1: атака | M1: навык | N1: ульта | O1: доп 1 | P1: бд1 1 | Q1: бд1 2 | R1: бд1 3 | S1: доп 2 | T1: бд2 1 | U1: бд2 2 | V1: бд2 3 | W1: доп 3 | X1: бд3 1 | Y1: бд3 2 | Z1: бд3 3 | AA1: бонус | AB1: талант духа | AC1: навык духа
A2: авантюрин | B2: Сохранение | C2: 5 | D2: Мнимый | E2: 6 | F2: =IF(AND(OR($E2=0,$E2=1,$E2=2),$C2=5),65,IF(AND($E2=3,$C2=5),62,IF(AND($E2=4,$C2=5),55,IF(AND($E2=5,$C2=5),35,IF($E2=6,0,IF(AND(OR($E2=0,$E2=1,$E2=2),$C2=4),50,IF(AND($E2=3,$C2=4),48,IF(AND($E2=4,$C2=4),43,IF(AND($E2=5,$C2=4),28,0))))))))) -> 0 | G2: Усмиряющий талисман | H2: Желания | I2: Янтарь | J2: Старые кошмары | K2: 10 | L2: 6 | M2: 10 | N2: 10 | O2: да | P2: да | Q2: да | R2: да | S2: да | T2: да | U2: да | V2: да | W2: да | X2: да | Y2: да | Z2: да | AA2: да | AB2: нет | AC2: нет
A3: байлу | B3: Изобилие | C3: 5 | D3: Электро | E3: 6 | F3: =IF(AND(OR($E3=0,$E3=1,$E3=2),$C3=5),65,IF(AND($E3=3,$C3=5),62,IF(AND($E3=4,$C3=5),55,IF(AND($E3=5,$C3=5),35,IF($E3=6,0,IF(AND(OR($E3=0,$E3=1,$E3=2),$C3=4),50,IF(AND($E3=3,$C3=4),48,IF(AND($E3=4,$C3=4),43,IF(AND($E3=5,$C3=4),28,0))))))))) -> 0 | G3: Электрическая корона тени прошлого | H3: Ядро | I3: Росток | J3: Конец мерзлоты | K3: 1 | L3: 1 | M3: 1 | N3: 1 | O3: нет | P3: нет | Q3: нет | R3: нет | S3: нет | T3: нет | U3: нет | V3: нет | W3: нет | X3: нет | Y3: нет | Z3: нет | AA3: нет | AB3: нет | AC3: нет
A4: броня | B4: Гармония | C4: 5 | D4: Ветер | E4: 6 | F4: =IF(AND(OR($E4=0,$E4=1,$E4=2),$C4=5),65,IF(AND($E4=3,$C4=5),62,IF(AND($E4=4,$C4=5),55,IF(AND($E4=5,$C4=5),35,IF($E4=6,0,IF(AND(OR($E4=0,$E4=1,$E4=2),$C4=4),50,IF(AND($E4=3,$C4=4),48,IF(AND($E4=4,$C4=4),43,IF(AND($E4=5,$C4=4),28,0))))))))) -> 0 | G4: Глаз бури | H4: Стражи | I4: Песнь | J4: Конец мерзлоты | K4: 1 | L4: 1 | M4: 1 | N4: 1 | O4: нет | P4: нет | Q4: нет | R4: нет | S4: нет | T4: нет | U4: нет | V4: нет | W4: нет | X4: нет | Y4: нет | Z4: нет | AA4: нет | AB4: нет | AC4: нет
A5: бутхилл | B5: Охота | C5: 5 | D5: Физ | E5: 6 | F5: =IF(AND(OR($E5=0,$E5=1,$E5=2),$C5=5),65,IF(AND($E5=3,$C5=5),62,IF(AND($E5=4,$C5=5),55,IF(AND($E5=5,$C5=5),35,IF($E5=6,0,IF(AND(OR($E5=0,$E5=1,$E5=2),$C5=4),50,IF(AND($E5=3,$C5=4),48,IF(AND($E5=4,$C5=4),43,IF(AND($E5=5,$C5=4),28,0))))))))) -> 0 | G5: Разрешение на работу КММ | H5: Желания | I5: Пуля | J5: Дань вежливости | K5: 1 | L5: 1 | M5: 1 | N5: 1 | O5: нет | P5: нет | Q5: нет | R5: нет | S5: нет | T5: нет | U5: нет | V5: нет | W5: нет | X5: нет | Y5: нет | Z5: нет | AA5: нет | AB5: нет | AC5: нет
A6: галлах | B6: Изобилие | C6: 4 | D6: Огонь | E6: 6 | F6: =IF(AND(OR($E6=0,$E6=1,$E6=2),$C6=5),65,IF(AND($E6=3,$C6=5),62,IF(AND($E6=4,$C6=5),55,IF(AND($E6=5,$C6=5),35,IF($E6=6,0,IF(AND(OR($E6=0,$E6=1,$E6=2),$C6=4),50,IF(AND($E6=3,$C6=4),48,IF(AND($E6=4,$C6=4),43,IF(AND($E6=5,$C6=4),28,0))))))))) -> 0 | G6: Пылающее сердце | H6: Сны | I6: Плод | J6: Старые кошмары | K6: 1 | L6: 1 | M6: 1 | N6: 1 | O6: нет | P6: нет | Q6: нет | R6: нет | S6: нет | T6: нет | U6: нет | V6: нет | W6: нет | X6: нет | Y6: нет | Z6: нет | AA6: нет | AB6: нет | AC6: нет
A7: гепард | B7: Сохранение | C7: 5 | D7: Лёд | E7: 6 | F7: =IF(AND(OR($E7=0,$E7=1,$E7=2),$C7=5),65,IF(AND($E7=3,$C7=5),62,IF(AND($E7=4,$C7=5),55,IF(AND($E7=5,$C7=5),35,IF($E7=6,0,IF(AND(OR($E7=0,$E7=1,$E7=2),$C7=4),50,IF(AND($E7=3,$C7=4),48,IF(AND($E7=4,$C7=4),43,IF(AND($E7=5,$C7=4),28,0))))))))) -> 0 | G7: Снежный рог | H7: Стражи | I7: Страж | J7: Конец мерзлоты | K7: 1 | L7: 1 | M7: 1 | N7: 1 | O7: нет | P7: нет | Q7: нет | R7: нет | S7: нет | T7: нет | U7: нет | V7: нет | W7: нет | X7: нет | Y7: нет | Z7: нет | AA7: нет | AB7: нет | AC7: нет
A8: герта | B8: Эрудиция | C8: 4 | D8: Лёд | E8: 6 | F8: =IF(AND(OR($E8=0,$E8=1,$E8=2),$C8=5),65,IF(AND($E8=3,$C8=5),62,IF(AND($E8=4,$C8=5),55,IF(AND($E8=5,$C8=5),35,IF($E8=6,0,IF(AND(OR($E8=0,$E8=1,$E8=2),$C8=4),50,IF(AND($E8=3,$C8=4),48,IF(AND($E8=4,$C8=4),43,IF(AND($E8=5,$C8=4),28,0))))))))) -> 0 | G8: Снежный рог | H8: Ядро | I8: Ключ | J8: Начало разрушения | K8: 1 | L8: 1 | M8: 1 | N8: 1 | O8: нет | P8: нет | Q8: нет | R8: нет | S8: нет | T8: нет | U8: нет | V8: нет | W8: нет | X8: нет | Y8: нет | Z8: нет | AA8: нет | AB8: нет | AC8: нет
A9: дань хэн | B9: Охота | C9: 4 | D9: Ветер | E9: 6 | F9: =IF(AND(OR($E9=0,$E9=1,$E9=2),$C9=5),65,IF(AND($E9=3,$C9=5),62,IF(AND($E9=4,$C9=5),55,IF(AND($E9=5,$C9=5),35,IF($E9=6,0,IF(AND(OR($E9=0,$E9=1,$E9=2),$C9=4),50,IF(AND($E9=3,$C9=4),48,IF(AND($E9=4,$C9=4),43,IF(AND($E9=5,$C9=4),28,0))))))))) -> 0 | G9: Глаз бури | H9: Ядро | I9: Копье | J9: Начало разрушения | K9: 1 | L9: 1 | M9: 1 | N9: 1 | O9: нет | P9: нет | Q9: нет | R9: нет | S9: нет | T9: нет | U9: нет | V9: нет | W9: нет | X9: нет | Y9: нет | Z9: нет | AA9: нет | AB9: нет | AC9: нет
A10: зарянка | B10: Гармония | C10: 5 | D10: Физ | E10: 6 | F10: =IF(AND(OR($E10=0,$E10=1,$E10=2),$C10=5),65,IF(AND($E10=3,$C10=5),62,IF(AND($E10=4,$C10=5),55,IF(AND($E10=5,$C10=5),35,IF($E10=6,0,IF(AND(OR($E10=0,$E10=1,$E10=2),$C10=4),50,IF(AND($E10=3,$C10=4),48,IF(AND($E10=4,$C10=4),43,IF(AND($E10=5,$C10=4),28,0))))))))) -> 0 | G10: Разрешение на работу КММ | H10: Сны | I10: Небеса | J10: Старые кошмары | K10: 1 | L10: 1 | M10: 1 | N10: 1 | O10: нет | P10: нет | Q10: нет | R10: нет | S10: нет | T10: нет | U10: нет | V10: нет | W10: нет | X10: нет | Y10: нет | Z10: нет | AA10: нет | AB10: нет | AC10: нет
A11: искорка | B11: Гармония | C11: 5 | D11: Квант | E11: 6 | F11: =IF(AND(OR($E11=0,$E11=1,$E11=2),$C11=5),65,IF(AND($E11=3,$C11=5),62,IF(AND($E11=4,$C11=5),55,IF(AND($E11=5,$C11=5),35,IF($E11=6,0,IF(AND(OR($E11=0,$E11=1,$E11=2),$C11=4),50,IF(AND($E11=3,$C11=4),48,IF(AND($E11=4,$C11=4),43,IF(AND($E11=5,$C11=4),28,0))))))))) -> 0 | G11: Огнемёт грёз | H11: Желания | I11: Небеса | J11: Старые кошмары | K11: 1 | L11: 1 | M11: 1 | N11: 1 | O11: нет | P11: нет | Q11: нет | R11: нет | S11: нет | T11: нет | U11: нет | V11: нет | W11: нет | X11: нет | Y11: нет | Z11: нет | AA11: нет | AB11: нет | AC11: нет
A12: кастория | B12: Память | C12: 5 | D12: Квант | E12: 6 | F12: =IF(AND(OR($E12=0,$E12=1,$E12=2),$C12=5),65,IF(AND($E12=3,$C12=5),62,IF(AND($E12=4,$C12=5),55,IF(AND($E12=5,$C12=5),35,IF($E12=6,0,IF(AND(OR($E12=0,$E12=1,$E12=2),$C12=4),50,IF(AND($E12=3,$C12=4),48,IF(AND($E12=4,$C12=4),43,IF(AND($E12=5,$C12=4),28,0))))))))) -> 0 | G12: Тусклый лунный блеск | H12: Эхо | I12: Бутон | J12: Поле битвы | K12: 10 | L12: 6 | M12: 10 | N12: 10 | O12: да | P12: да | Q12: да | R12: да | S12: да | T12: да | U12: да | V12: да | W12: да | X12: да | Y12: да | Z12: да | AA12: да | AB12: 6 | AC12: 6
A13: келус | B13: Разрушение | C13: 5 | D13: Физ | E13: 6 | F13: =IF(AND(OR($E13=0,$E13=1,$E13=2),$C13=5),65,IF(AND($E13=3,$C13=5),62,IF(AND($E13=4,$C13=5),55,IF(AND($E13=5,$C13=5),35,IF($E13=6,0,IF(AND(OR($E13=0,$E13=1,$E13=2),$C13=4),50,IF(AND($E13=3,$C13=4),48,IF(AND($E13=4,$C13=4),43,IF(AND($E13=5,$C13=4),28,0))))))))) -> 0 | H13: Амбиции | I13: Клинок | J13: Начало разрушения | K13: 1 | L13: 1 | M13: 1 | N13: 1 | O13: нет | P13: нет | Q13: нет | R13: нет | S13: нет | T13: нет | U13: нет | V13: нет | W13: нет | X13: нет | Y13: нет | Z13: нет | AA13: нет | AB13: нет | AC13: нет
A14: келус | B14: Сохранение | C14: 5 | D14: Огонь | E14: 6 | F14: =IF(AND(OR($E14=0,$E14=1,$E14=2),$C14=5),65,IF(AND($E14=3,$C14=5),62,IF(AND($E14=4,$C14=5),55,IF(AND($E14=5,$C14=5),35,IF($E14=6,0,IF(AND(OR($E14=0,$E14=1,$E14=2),$C14=4),50,IF(AND($E14=3,$C14=4),48,IF(AND($E14=4,$C14=4),43,IF(AND($E14=5,$C14=4),28,0))))))))) -> 0 | H14: Амбиции | I14: Страж | J14: Начало разрушения | K14: 1 | L14: 1 | M14: 1 | N14: 1 | O14: нет | P14: нет | Q14: нет | R14: нет | S14: нет | T14: нет | U14: нет | V14: нет | W14: нет | X14: нет | Y14: нет | Z14: нет | AA14: нет | AB14: нет | AC14: нет
A15: келус | B15: Память | C15: 5 | D15: Лёд | E15: 6 | F15: =IF(AND(OR($E15=0,$E15=1,$E15=2),$C15=5),65,IF(AND($E15=3,$C15=5),62,IF(AND($E15=4,$C15=5),55,IF(AND($E15=5,$C15=5),35,IF($E15=6,0,IF(AND(OR($E15=0,$E15=1,$E15=2),$C15=4),50,IF(AND($E15=3,$C15=4),48,IF(AND($E15=4,$C15=4),43,IF(AND($E15=5,$C15=4),28,0))))))))) -> 0 | H15: Амбиции | I15: Бутон | J15: Поле битвы | K15: 3 | L15: 2 | M15: 3 | N15: 7 | O15: нет | P15: нет | Q15: нет | R15: нет | S15: нет | T15: нет | U15: нет | V15: нет | W15: нет | X15: нет | Y15: нет | Z15: нет | AA15: нет | AB15: 1 | AC15: 1
A16: келус | B16: Гармония | C16: 5 | D16: Мнимый | E16: 6 | F16: =IF(AND(OR($E16=0,$E16=1,$E16=2),$C16=5),65,IF(AND($E16=3,$C16=5),62,IF(AND($E16=4,$C16=5),55,IF(AND($E16=5,$C16=5),35,IF($E16=6,0,IF(AND(OR($E16=0,$E16=1,$E16=2),$C16=4),50,IF(AND($E16=3,$C16=4),48,IF(AND($E16=4,$C16=4),43,IF(AND($E16=5,$C16=4),28,0))))))))) -> 0 | H16: Стражи | I16: Небеса | J16: Старые кошмары | K16: 1 | L16: 1 | M16: 1 | N16: 1 | O16: нет | P16: нет | Q16: нет | R16: нет | S16: нет | T16: нет | U16: нет | V16: нет | W16: нет | X16: нет | Y16: нет | Z16: нет | AA16: нет | AB16: нет | AC16: нет
A17: м7 | B17: Охота | C17: 4 | D17: Мнимый | E17: 6 | F17: =F16 -> 0 | G17: Снежный рог | H17: Амбиции | I17: Пуля | J17: Начало разрушения | K17: 1 | L17: 1 | M17: 1 | N17: 1 | O17: нет | P17: нет | Q17: нет | R17: нет | S17: нет | T17: нет | U17: нет | V17: нет | W17: нет | X17: нет | Y17: нет | Z17: нет | AA17: нет | AB17: нет | AC17: нет
A18: м7 | B18: Сохранение | C18: 4 | D18: Лёд | E18: 6 | F18: =IF(AND(OR($E18=0,$E18=1,$E18=2),$C18=5),65,IF(AND($E18=3,$C18=5),62,IF(AND($E18=4,$C18=5),55,IF(AND($E18=5,$C18=5),35,IF($E18=6,0,IF(AND(OR($E18=0,$E18=1,$E18=2),$C18=4),50,IF(AND($E18=3,$C18=4),48,IF(AND($E18=4,$C18=4),43,IF(AND($E18=5,$C18=4),28,0))))))))) -> 0 | G18: Снежный рог | H18: Амбиции | I18: Страж | J18: Начало разрушения | K18: 1 | L18: 1 | M18: 1 | N18: 1 | O18: нет | P18: нет | Q18: нет | R18: нет | S18: нет | T18: нет | U18: нет | V18: нет | W18: нет | X18: нет | Y18: нет | Z18: нет | AA18: нет | AB18: нет | AC18: нет
A19: мидей | B19: Разрушение | C19: 5 | D19: Мнимый | E19: 6 | F19: =IF(AND(OR($E19=0,$E19=1,$E19=2),$C19=5),65,IF(AND($E19=3,$C19=5),62,IF(AND($E19=4,$C19=5),55,IF(AND($E19=5,$C19=5),35,IF($E19=6,0,IF(AND(OR($E19=0,$E19=1,$E19=2),$C19=4),50,IF(AND($E19=3,$C19=4),48,IF(AND($E19=4,$C19=4),43,IF(AND($E19=5,$C19=4),28,0))))))))) -> 0 | G19: Предвестник раздора | H19: Плоть | I19: Клыки | J19: Поле битвы | K19: 1 | L19: 1 | M19: 1 | N19: 1 | O19: нет | P19: нет | Q19: нет | R19: нет | S19: нет | T19: нет | U19: нет | V19: нет | W19: нет | X19: нет | Y19: нет | Z19: нет | AA19: нет | AB19: нет | AC19: нет
A20: миша | B20: Разрушение | C20: 4 | D20: Лёд | E20: 6 | F20: =IF(AND(OR($E20=0,$E20=1,$E20=2),$C20=5),65,IF(AND($E20=3,$C20=5),62,IF(AND($E20=4,$C20=5),55,IF(AND($E20=5,$C20=5),35,IF($E20=6,0,IF(AND(OR($E20=0,$E20=1,$E20=2),$C20=4),50,IF(AND($E20=3,$C20=4),48,IF(AND($E20=4,$C20=4),43,IF(AND($E20=5,$C20=4),28,0))))))))) -> 0 | G20: Холодильник грёз | H20: Сны | I20: Клыки | J20: Старые кошмары | K20: 1 | L20: 1 | M20: 1 | N20: 1 | O20: нет | P20: нет | Q20: нет | R20: нет | S20: нет | T20: нет | U20: нет | V20: нет | W20: нет | X20: нет | Y20: нет | Z20: нет | AA20: нет | AB20: нет | AC20: нет
A21: Монцзе | B21: Охота | C21: 4 | D21: Электро | E21: 6 | F21: =IF(AND(OR($E21=0,$E21=1,$E21=2),$C21=5),65,IF(AND($E21=3,$C21=5),62,IF(AND($E21=4,$C21=5),55,IF(AND($E21=5,$C21=5),35,IF($E21=6,0,IF(AND(OR($E21=0,$E21=1,$E21=2),$C21=4),50,IF(AND($E21=3,$C21=4),48,IF(AND($E21=4,$C21=4),43,IF(AND($E21=5,$C21=4),28,0))))))))) -> 0 | G21: Гвоздь звериного гроба | H21: Хаос | I21: Пуля | J21: Поле битвы | K21: 1 | L21: 1 | M21: 1 | N21: 1 | O21: нет | P21: нет | Q21: нет | R21: нет | S21: нет | T21: нет | U21: нет | V21: нет | W21: нет | X21: нет | Y21: нет | Z21: нет | AA21: нет | AB21: нет | AC21: нет
A22: пела | B22: Небытие | C22: 4 | D22: Лёд | E22: 6 | F22: =IF(AND(OR($E22=0,$E22=1,$E22=2),$C22=5),65,IF(AND($E22=3,$C22=5),62,IF(AND($E22=4,$C22=5),55,IF(AND($E22=5,$C22=5),35,IF($E22=6,0,IF(AND(OR($E22=0,$E22=1,$E22=2),$C22=4),50,IF(AND($E22=3,$C22=4),48,IF(AND($E22=4,$C22=4),43,IF(AND($E22=5,$C22=4),28,0))))))))) -> 0 | G22: Снежный рог | H22: Ядро | I22: Обсидиан | J22: Конец мерзлоты | K22: 1 | L22: 1 | M22: 1 | N22: 1 | O22: нет | P22: нет | Q22: нет | R22: нет | S22: нет | T22: нет | U22: нет | V22: нет | W22: нет | X22: нет | Y22: нет | Z22: нет | AA22: нет | AB22: нет | AC22: нет
A23: рацио | B23: Охота | C23: 5 | D23: Мнимый | E23: 6 | F23: =IF(AND(OR($E23=0,$E23=1,$E23=2),$C23=5),65,IF(AND($E23=3,$C23=5),62,IF(AND($E23=4,$C23=5),55,IF(AND($E23=5,$C23=5),35,IF($E23=6,0,IF(AND(OR($E23=0,$E23=1,$E23=2),$C23=4),50,IF(AND($E23=3,$C23=4),48,IF(AND($E23=4,$C23=4),43,IF(AND($E23=5,$C23=4),28,0))))))))) -> 0 | G23: Усмиряющий талисман | H23: Амбиции | I23: Копье | J23: Старые кошмары | K23: 1 | L23: 1 | M23: 1 | N23: 1 | O23: нет | P23: нет | Q23: нет | R23: нет | S23: нет | T23: нет | U23: нет | V23: нет | W23: нет | X23: нет | Y23: нет | Z23: нет | AA23: нет | AB23: нет | AC23: нет
A24: Сандей | B24: Гармония | C24: 5 | D24: Мнимый | E24: 6 | F24: =IF(AND(OR($E24=0,$E24=1,$E24=2),$C24=5),65,IF(AND($E24=3,$C24=5),62,IF(AND($E24=4,$C24=5),55,IF(AND($E24=5,$C24=5),35,IF($E24=6,0,IF(AND(OR($E24=0,$E24=1,$E24=2),$C24=4),50,IF(AND($E24=3,$C24=4),48,IF(AND($E24=4,$C24=4),43,IF(AND($E24=5,$C24=4),28,0))))))))) -> 0 | G24: Аккордный мираж | H24: Желания | I24: Небеса | J24: Дань вежливости | K24: 1 | L24: 1 | M24: 1 | N24: 1 | O24: нет | P24: нет | Q24: нет | R24: нет | S24: нет | T24: нет | U24: нет | V24: нет | W24: нет | X24: нет | Y24: нет | Z24: нет | AA24: нет | AB24: нет | AC24: нет
A25: светлячок | B25: Разрушение | C25: 5 | D25: Огонь | E25: 6 | F25: =IF(AND(OR($E25=0,$E25=1,$E25=2),$C25=5),65,IF(AND($E25=3,$C25=5),62,IF(AND($E25=4,$C25=5),55,IF(AND($E25=5,$C25=5),35,IF($E25=6,0,IF(AND(OR($E25=0,$E25=1,$E25=2),$C25=4),50,IF(AND($E25=3,$C25=4),48,IF(AND($E25=4,$C25=4),43,IF(AND($E25=5,$C25=4),28,0))))))))) -> 0 | G25: Пылающее сердце | H25: Желания | I25: Клыки | J25: Дань вежливости | K25: 1 | L25: 1 | M25: 1 | N25: 1 | O25: нет | P25: нет | Q25: нет | R25: нет | S25: нет | T25: нет | U25: нет | V25: нет | W25: нет | X25: нет | Y25: нет | Z25: нет | AA25: нет | AB25: нет | AC25: нет
A26: сервал | B26: Эрудиция | C26: 4 | D26: Электро | E26: 6 | F26: =IF(AND(OR($E26=0,$E26=1,$E26=2),$C26=5),65,IF(AND($E26=3,$C26=5),62,IF(AND($E26=4,$C26=5),55,IF(AND($E26=5,$C26=5),35,IF($E26=6,0,IF(AND(OR($E26=0,$E26=1,$E26=2),$C26=4),50,IF(AND($E26=3,$C26=4),48,IF(AND($E26=4,$C26=4),43,IF(AND($E26=5,$C26=4),28,0))))))))) -> 0 | G26: Электрическая корона тени прошлого | H26: Стражи | I26: Ключ | J26: Конец мерзлоты | K26: 1 | L26: 1 | M26: 1 | N26: 1 | O26: нет | P26: нет | Q26: нет | R26: нет | S26: нет | T26: нет | U26: нет | V26: нет | W26: нет | X26: нет | Y26: нет | Z26: нет | AA26: нет | AB26: нет | AC26: нет
A27: фаэнон | B27: Разрушение | C27: 5 | D27: Физ | E27: 6 | F27: =IF(AND(OR($E27=0,$E27=1,$E27=2),$C27=5),65,IF(AND($E27=3,$C27=5),62,IF(AND($E27=4,$C27=5),55,IF(AND($E27=5,$C27=5),35,IF($E27=6,0,IF(AND(OR($E27=0,$E27=1,$E27=2),$C27=4),50,IF(AND($E27=3,$C27=4),48,IF(AND($E27=4,$C27=4),43,IF(AND($E27=5,$C27=4),28,0))))))))) -> 0 | G27: Агрессивный сгусток | H27: Эхо | I27: Клыки | J27: Взгляд на сумерки | K27: 1 | L27: 1 | M27: 1 | N27: 1 | O27: нет | P27: нет | Q27: нет | R27: нет | S27: нет | T27: нет | U27: нет | V27: нет | W27: нет | X27: нет | Y27: нет | Z27: нет | AA27: нет | AB27: нет | AC27: нет
A28: ханья | B28: Гармония | C28: 4 | D28: Физ | E28: 6 | F28: =IF(AND(OR($E28=0,$E28=1,$E28=2),$C28=5),65,IF(AND($E28=3,$C28=5),62,IF(AND($E28=4,$C28=5),55,IF(AND($E28=5,$C28=5),35,IF($E28=6,0,IF(AND(OR($E28=0,$E28=1,$E28=2),$C28=4),50,IF(AND($E28=3,$C28=4),48,IF(AND($E28=4,$C28=4),43,IF(AND($E28=5,$C28=4),28,0))))))))) -> 0 | G28: Призрачный пропуск | H28: Хаос | I28: Песнь | J28: Семя бессмертия | K28: 1 | L28: 1 | M28: 1 | N28: 1 | O28: нет | P28: нет | Q28: нет | R28: нет | S28: нет | T28: нет | U28: нет | V28: нет | W28: нет | X28: нет | Y28: нет | Z28: нет | AA28: нет | AB28: нет | AC28: нет
A29: цинцюэ | B29: Эрудиция | C29: 4 | D29: Квант | E29: 6 | F29: =IF(AND(OR($E29=0,$E29=1,$E29=2),$C29=5),65,IF(AND($E29=3,$C29=5),62,IF(AND($E29=4,$C29=5),55,IF(AND($E29=5,$C29=5),35,IF($E29=6,0,IF(AND(OR($E29=0,$E29=1,$E29=2),$C29=4),50,IF(AND($E29=3,$C29=4),48,IF(AND($E29=4,$C29=4),43,IF(AND($E29=5,$C29=4),28,0))))))))) -> 0 | G29: Чугун пустоты | H29: Амбиции | I29: Ключ | J29: Конец мерзлоты | K29: 1 | L29: 1 | M29: 1 | N29: 1 | O29: нет | P29: нет | Q29: нет | R29: нет | S29: нет | T29: нет | U29: нет | V29: нет | W29: нет | X29: нет | Y29: нет | Z29: нет | AA29: нет | AB29: нет | AC29: нет
... A49: яньцин | B49: Охота | C49: 5 | D49: Лёд | E49: 1 | F49: =IF(AND(OR($E49=0,$E49=1,$E49=2),$C49=5),65,IF(AND($E49=3,$C49=5),62,IF(AND($E49=4,$C49=5),55,IF(AND($E49=5,$C49=5),35,IF($E49=6,0,IF(AND(OR($E49=0,$E49=1,$E49=2),$C49=4),50,IF(AND($E49=3,$C49=4),48,IF(AND($E49=4,$C49=4),43,IF(AND($E49=5,$C49=4),28,0))))))))) -> 65 | G49: Гелидный хитин | H49: Амбиции | I49: Копье | J49: Конец мерзлоты | K49: 1 | L49: 1 | M49: 1 | N49: 1 | O49: нет | P49: нет | Q49: нет | R49: нет | S49: нет | T49: нет | U49: нет | V49: нет | W49: нет | X49: нет | Y49: нет | Z49: нет | AA49: нет | AB49: нет | AC49: нет
A50: аглая | B50: Память | C50: 5 | D50: Электро | E50: 0 | F50: =IF(AND(OR($E50=0,$E50=1,$E50=2),$C50=5),65,IF(AND($E50=3,$C50=5),62,IF(AND($E50=4,$C50=5),55,IF(AND($E50=5,$C50=5),35,IF($E50=6,0,IF(AND(OR($E50=0,$E50=1,$E50=2),$C50=4),50,IF(AND($E50=3,$C50=4),48,IF(AND($E50=4,$C50=4),43,IF(AND($E50=5,$C50=4),28,0))))))))) -> 65 | G50: Гвоздь звериного гроба | H50: Плоть | I50: Бутон | J50: Поле битвы | K50: 1 | L50: 1 | M50: 1 | N50: 1 | O50: нет | P50: нет | Q50: нет | R50: нет | S50: нет | T50: нет | U50: нет | V50: нет | W50: нет | X50: нет | Y50: нет | Z50: нет | AA50: нет | AB50: 1 | AC50: 1
A51: анакса | B51: Эрудиция | C51: 5 | D51: Ветер | E51: 0 | F51: =IF(AND(OR($E51=0,$E51=1,$E51=2),$C51=5),65,IF(AND($E51=3,$C51=5),62,IF(AND($E51=4,$C51=5),55,IF(AND($E51=5,$C51=5),35,IF($E51=6,0,IF(AND(OR($E51=0,$E51=1,$E51=2),$C51=4),50,IF(AND($E51=3,$C51=4),48,IF(AND($E51=4,$C51=4),43,IF(AND($E51=5,$C51=4),28,0))))))))) -> 65 | G51: Бокал пьяных времен | H51: Эхо | I51: Эскиз | J51: Дань вежливости | K51: 1 | L51: 1 | M51: 1 | N51: 1 | O51: нет | P51: нет | Q51: нет | R51: нет | S51: нет | T51: нет | U51: нет | V51: нет | W51: нет | X51: нет | Y51: нет | Z51: нет | AA51: нет | AB51: нет | AC51: нет
A52: арчер | B52: Охота | C52: 5 | D52: Квант | E52: 0 | F52: =IF(AND(OR($E52=0,$E52=1,$E52=2),$C52=5),65,IF(AND($E52=3,$C52=5),62,IF(AND($E52=4,$C52=5),55,IF(AND($E52=5,$C52=5),35,IF($E52=6,0,IF(AND(OR($E52=0,$E52=1,$E52=2),$C52=4),50,IF(AND($E52=3,$C52=4),48,IF(AND($E52=4,$C52=4),43,IF(AND($E52=5,$C52=4),28,0))))))))) -> 65 | G52: Тусклый лунный блеск | H52: Ядро | I52: Пуля | J52: Конец мерзлоты | K52: 1 | L52: 1 | M52: 1 | N52: 1 | O52: нет | P52: нет | Q52: нет | R52: нет | S52: нет | T52: нет | U52: нет | V52: нет | W52: нет | X52: нет | Y52: нет | Z52: нет | AA52: нет | AB52: нет | AC52: нет
A53: ахерон | B53: Небытие | C53: 5 | D53: Электро | E53: 0 | F53: =IF(AND(OR($E53=0,$E53=1,$E53=2),$C53=5),65,IF(AND($E53=3,$C53=5),62,IF(AND($E53=4,$C53=5),55,IF(AND($E53=5,$C53=5),35,IF($E53=6,0,IF(AND(OR($E53=0,$E53=1,$E53=2),$C53=4),50,IF(AND($E53=3,$C53=4),48,IF(AND($E53=4,$C53=4),43,IF(AND($E53=5,$C53=4),28,0))))))))) -> 65 | G53: Электрический посох оборотня | H53: Сны | I53: Эссенция | J53: Старые кошмары | K53: 1 | L53: 1 | M53: 1 | N53: 1 | O53: нет | P53: нет | Q53: нет | R53: нет | S53: нет | T53: нет | U53: нет | V53: нет | W53: нет | X53: нет | Y53: нет | Z53: нет | AA53: нет | AB53: нет | AC53: нет
A54: великая герта | B54: Эрудиция | C54: 5 | D54: Лёд | E54: 0 | F54: =IF(AND(OR($E54=0,$E54=1,$E54=2),$C54=5),65,IF(AND($E54=3,$C54=5),62,IF(AND($E54=4,$C54=5),55,IF(AND($E54=5,$C54=5),35,IF($E54=6,0,IF(AND(OR($E54=0,$E54=1,$E54=2),$C54=4),50,IF(AND($E54=3,$C54=4),48,IF(AND($E54=4,$C54=4),43,IF(AND($E54=5,$C54=4),28,0))))))))) -> 65 | G54: Холодильник грёз | H54: Ядро | I54: Эскиз | J54: Поле битвы | K54: 1 | L54: 1 | M54: 1 | N54: 1 | O54: нет | P54: нет | Q54: нет | R54: нет | S54: нет | T54: нет | U54: нет | V54: нет | W54: нет | X54: нет | Y54: нет | Z54: нет | AA54: нет | AB54: нет | AC54: нет
A55: волк | B55: Небытие | C55: 5 | D55: Квант | E55: 0 | F55: =IF(AND(OR($E55=0,$E55=1,$E55=2),$C55=5),65,IF(AND($E55=3,$C55=5),62,IF(AND($E55=4,$C55=5),55,IF(AND($E55=5,$C55=5),35,IF($E55=6,0,IF(AND(OR($E55=0,$E55=1,$E55=2),$C55=4),50,IF(AND($E55=3,$C55=4),48,IF(AND($E55=4,$C55=4),43,IF(AND($E55=5,$C55=4),28,0))))))))) -> 65 | G55: Чугун пустоты | H55: Двигатель | I55: Обсидиан | J55: Начало разрушения | K55: 1 | L55: 1 | M55: 1 | N55: 1 | O55: нет | P55: нет | Q55: нет | R55: нет | S55: нет | T55: нет | U55: нет | V55: нет | W55: нет | X55: нет | Y55: нет | Z55: нет | AA55: нет | AB55: нет | AC55: нет
A56: гиацина | B56: Память | C56: 5 | D56: Ветер | E56: 0 | F56: =IF(AND(OR($E56=0,$E56=1,$E56=2),$C56=5),65,IF(AND($E56=3,$C56=5),62,IF(AND($E56=4,$C56=5),55,IF(AND($E56=5,$C56=5),35,IF($E56=6,0,IF(AND(OR($E56=0,$E56=1,$E56=2),$C56=4),50,IF(AND($E56=3,$C56=4),48,IF(AND($E56=4,$C56=4),43,IF(AND($E56=5,$C56=4),28,0))))))))) -> 65 | G56: Бокал пьяных времен | H56: Плоть | I56: Бутон | J56: Дань вежливости | K56: 1 | L56: 1 | M56: 1 | N56: 1 | O56: нет | P56: нет | Q56: нет | R56: нет | S56: нет | T56: нет | U56: нет | V56: нет | W56: нет | X56: нет | Y56: нет | Z56: нет | AA56: нет | AB56: 1 | AC56: 1
A57: глесилена | B57: Небытие | C57: 5 | D57: Физ | E57: 0 | F57: =IF(AND(OR($E57=0,$E57=1,$E57=2),$C57=5),65,IF(AND($E57=3,$C57=5),62,IF(AND($E57=4,$C57=5),55,IF(AND($E57=5,$C57=5),35,IF($E57=6,0,IF(AND(OR($E57=0,$E57=1,$E57=2),$C57=4),50,IF(AND($E57=3,$C57=4),48,IF(AND($E57=4,$C57=4),43,IF(AND($E57=5,$C57=4),28,0))))))))) -> 65 | G57: Агрессивный сгусток | H57: Плоть | I57: Эссенция | J57: Взгляд на сумерки | K57: 1 | L57: 1 | M57: 1 | N57: 1 | O57: нет | P57: нет | Q57: нет | R57: нет | S57: нет | T57: нет | U57: нет | V57: нет | W57: нет | X57: нет | Y57: нет | Z57: нет | AA57: нет | AB57: нет | AC57: нет
A58: зеле | B58: Охота | C58: 5 | D58: Квант | E58: 0 | F58: =IF(AND(OR($E58=0,$E58=1,$E58=2),$C58=5),65,IF(AND($E58=3,$C58=5),62,IF(AND($E58=4,$C58=5),55,IF(AND($E58=5,$C58=5),35,IF($E58=6,0,IF(AND(OR($E58=0,$E58=1,$E58=2),$C58=4),50,IF(AND($E58=3,$C58=4),48,IF(AND($E58=4,$C58=4),43,IF(AND($E58=5,$C58=4),28,0))))))))) -> 65 | G58: Чугун пустоты | H58: Амбиции | I58: Копье | J58: Конец мерзлоты | K58: 1 | L58: 1 | M58: 1 | N58: 1 | O58: нет | P58: нет | Q58: нет | R58: нет | S58: нет | T58: нет | U58: нет | V58: нет | W58: нет | X58: нет | Y58: нет | Z58: нет | AA58: нет | AB58: нет | AC58: нет
A59: кафка | B59: Небытие | C59: 5 | D59: Электро | E59: 0 | F59: =IF(AND(OR($E59=0,$E59=1,$E59=2),$C59=5),65,IF(AND($E59=3,$C59=5),62,IF(AND($E59=4,$C59=5),55,IF(AND($E59=5,$C59=5),35,IF($E59=6,0,IF(AND(OR($E59=0,$E59=1,$E59=2),$C59=4),50,IF(AND($E59=3,$C59=4),48,IF(AND($E59=4,$C59=4),43,IF(AND($E59=5,$C59=4),28,0))))))))) -> 65 | G59: Электрический посох оборотня | H59: Амбиции | I59: Обсидиан | J59: Семя бессмертия | K59: 1 | L59: 1 | M59: 1 | N59: 1 | O59: нет | P59: нет | Q59: нет | R59: нет | S59: нет | T59: нет | U59: нет | V59: нет | W59: нет | X59: нет | Y59: нет | Z59: нет | AA59: нет | AB59: нет | AC59: нет
...

Sheet Хср боссы
E1: р
A2: Агрессивный сгусток | B2: 0 | C2: =SUMIF('Хср персы'!G:G,A2,'Хср персы'!F:F) -> 65 | D2: =C2-B2 -> 65 | E2: =IF(MOD(D2,5)=0,D2/5,INT(D2/5)+1) -> 13 | F2: =E2*30 -> 390 | G2: =F$2 -> 390 | H2: =E2*5-D2 -> 0
A3: Предвестник раздора | B3: 0 | C3: =SUMIF('Хср персы'!G:G,A3,'Хср персы'!F:F) -> 0 | D3: =C3-B3 -> 0 | E3: =IF(MOD(D3,5)=0,D3/5,INT(D3/5)+1) -> 0 | F3: =E3*30 -> 0 | G3: =SUM($F$2:F3) -> 390 | H3: =E3*5-D3 -> 0
A4: Сумеречный бутон | B4: 0 | C4: =SUMIF('Хср персы'!G:G,A4,'Хср персы'!F:F) -> 65 | D4: =C4-B4 -> 65 | E4: =IF(MOD(D4,5)=0,D4/5,INT(D4/5)+1) -> 13 | F4: =E4*30 -> 390 | G4: =SUM($F$2:F4) -> 780 | H4: =E4*5-D4 -> 0
A5: Тусклый лунный блеск | B5: 65 | C5: =SUMIF('Хср персы'!G:G,A5,'Хср персы'!F:F) -> 195 | D5: =C5-B5 -> 130 | E5: =IF(MOD(D5,5)=0,D5/5,INT(D5/5)+1) -> 26 | F5: =E5*30 -> 780 | G5: =SUM($F$2:F5) -> 1560 | H5: =E5*5-D5 -> 0
A6: Аккордный мираж | B6: =C6 -> 65 | C6: =SUMIF('Хср персы'!G:G,A6,'Хср персы'!F:F) -> 65 | D6: =C6-B6 -> 0 | E6: =IF(MOD(D6,5)=0,D6/5,INT(D6/5)+1) -> 0 | F6: =E6*30 -> 0 | G6: =SUM($F$2:F6) -> 1560 | H6: =E6*5-D6 -> 0
A7: Бокал пьяных времен | B7: =C7 -> 260 | C7: =SUMIF('Хср персы'!G:G,A7,'Хср персы'!F:F) -> 260 | D7: =C7-B7 -> 0 | E7: =IF(MOD(D7,5)=0,D7/5,INT(D7/5)+1) -> 0 | F7: =E7*30 -> 0 | G7: =SUM($F$2:F7) -> 1560 | H7: =E7*5-D7 -> 0
A8: Гвоздь звериного гроба | B8: =C8 -> 65 | C8: =SUMIF('Хср персы'!G:G,A8,'Хср персы'!F:F) -> 65 | D8: =C8-B8 -> 0 | E8: =IF(MOD(D8,5)=0,D8/5,INT(D8/5)+1) -> 0 | F8: =E8*30 -> 0 | G8: =SUM($F$2:F8) -> 1560 | H8: =E8*5-D8 -> 0
A9: Гелидный хитин | B9: 3 | C9: =SUMIF('Хср персы'!G:G,A9,'Хср персы'!F:F) -> 192 | D9: =C9-B9 -> 189 | E9: =IF(MOD(D9,5)=0,D9/5,INT(D9/5)+1) -> 38 | F9: =E9*30 -> 1140 | G9: =SUM($F$2:F9) -> 2700 | H9: =E9*5-D9 -> 1
A10: Глаз бури | B10: =C10 -> 28 | C10: =SUMIF('Хср персы'!G:G,A10,'Хср персы'!F:F) -> 28 | D10: =C10-B10 -> 0 | E10: =IF(MOD(D10,5)=0,D10/5,INT(D10/5)+1) -> 0 | F10: =E10*30 -> 0 | G10: =SUM($F$2:F10) -> 2700 | H10: =E10*5-D10 -> 0
A11: Золотая корона тени прошлого | B11: =C11 -> 155 | C11: =SUMIF('Хср персы'!G:G,A11,'Хср персы'!F:F) -> 155 | D11: =C11-B11 -> 0 | E11: =IF(MOD(D11,5)=0,D11/5,INT(D11/5)+1) -> 0 | F11: =E11*30 -> 0 | G11: =SUM($F$2:F11) -> 2700 | H11: =E11*5-D11 -> 0
A12: Обезьяний шип | B12: 0 | C12: =SUMIF('Хср персы'!G:G,A12,'Хср персы'!F:F) -> 161 | D12: =C12-B12 -> 161 | E12: =IF(MOD(D12,5)=0,D12/5,INT(D12/5)+1) -> 33 | F12: =E12*30 -> 990 | G12: =SUM($F$2:F12) -> 3690 | H12: =E12*5-D12 -> 4
A13: Огнемёт грёз | B13: =C13 -> 65 | C13: =SUMIF('Хср персы'!G:G,A13,'Хср персы'!F:F) -> 65 | D13: =C13-B13 -> 0 | E13: =IF(MOD(D13,5)=0,D13/5,INT(D13/5)+1) -> 0 | F13: =E13*30 -> 0 | G13: =SUM($F$2:F13) -> 3690 | H13: =E13*5-D13 -> 0
A14: Прах вознёсшейся | B14: 0 | C14: =SUMIF('Хср персы'!G:G,A14,'Хср персы'!F:F) -> 195 | D14: =C14-B14 -> 195 | E14: =IF(MOD(D14,5)=0,D14/5,INT(D14/5)+1) -> 39 | F14: =E14*30 -> 1170 | G14: =SUM($F$2:F14) -> 4860 | H14: =E14*5-D14 -> 0
A15: Прах вознёсшейся | B15: 0 | C15: =SUMIF('Хср персы'!G:G,A15,'Хср персы'!F:F) -> 195 | D15: =C15-B15 -> 195 | E15: =IF(MOD(D15,5)=0,D15/5,INT(D15/5)+1) -> 39 | F15: =E15*30 -> 1170 | G15: =SUM($F$2:F15) -> 6030 | H15: =E15*5-D15 -> 0
A16: Призрачный пропуск | B16: =C16 -> 55 | C16: =SUMIF('Хср персы'!G:G,A16,'Хср персы'!F:F) -> 55 | D16: =C16-B16 -> 0 | E16: =IF(MOD(D16,5)=0,D16/5,INT(D16/5)+1) -> 0 | F16: =E16*30 -> 0 | G16: =SUM($F$2:F16) -> 6030 | H16: =E16*5-D16 -> 0
A17: Пылающее сердце | B17: =C17 -> 130 | C17: =SUMIF('Хср персы'!G:G,A17,'Хср персы'!F:F) -> 130 | D17: =C17-B17 -> 0 | E17: =IF(MOD(D17,5)=0,D17/5,INT(D17/5)+1) -> 0 | F17: =E17*30 -> 0 | G17: =SUM($F$2:F17) -> 6030 | H17: =E17*5-D17 -> 0
A18: Разрешение на работу КММ | B18: =C18 -> 65 | C18: =SUMIF('Хср персы'!G:G,A18,'Хср персы'!F:F) -> 65 | D18: =C18-B18 -> 0 | E18: =IF(MOD(D18,5)=0,D18/5,INT(D18/5)+1) -> 0 | F18: =E18*30 -> 0 | G18: =SUM($F$2:F18) -> 6030 | H18: =E18*5-D18 -> 0
A19: Раскалённое лезвие | B19: 0 | C19: =SUMIF('Хср персы'!G:G,A19,'Хср персы'!F:F) -> 178 | D19: =C19-B19 -> 178 | E19: =IF(MOD(D19,5)=0,D19/5,INT(D19/5)+1) -> 36 | F19: =E19*30 -> 1080 | G19: =SUM($F$2:F19) -> 7110 | H19: =E19*5-D19 -> 2
A20: Сломанные зубы железного волка | B20: =C20 -> 139 | C20: =SUMIF('Хср персы'!G:G,A20,'Хср персы'!F:F) -> 139 | D20: =C20-B20 -> 0 | E20: =IF(MOD(D20,5)=0,D20/5,INT(D20/5)+1) -> 0 | F20: =E20*30 -> 0 | G20: =SUM($F$2:F20) -> 7110 | H20: =E20*5-D20 -> 0
A21: Снежный рог | B21: =C21 -> 0 | C21: =SUMIF('Хср персы'!G:G,A21,'Хср персы'!F:F) -> 0 | D21: =C21-B21 -> 0 | E21: =IF(MOD(D21,5)=0,D21/5,INT(D21/5)+1) -> 0 | F21: =E21*30 -> 0 | G21: =SUM($F$2:F21) -> 7110 | H21: =E21*5-D21 -> 0
A22: Усмиряющий талисман | B22: =C22 -> 62 | C22: =SUMIF('Хср персы'!G:G,A22,'Хср персы'!F:F) -> 62 | D22: =C22-B22 -> 0 | E22: =IF(MOD(D22,5)=0,D22/5,INT(D22/5)+1) -> 0 | F22: =E22*30 -> 0 | G22: =SUM($F$2:F22) -> 7110 | H22: =E22*5-D22 -> 0
A23: Холодильник грёз | B23: 0 | C23: =SUMIF('Хср персы'!G:G,A23,'Хср персы'!F:F) -> 65 | D23: =C23-B23 -> 65 | E23: =IF(MOD(D23,5)=0,D23/5,INT(D23/5)+1) -> 13 | F23: =E23*30 -> 390 | G23: =SUM($F$2:F23) -> 7500 | H23: =E23*5-D23 -> 0 | I23: =SUM(F:F) -> 9660 | J23: =ROUNDUP(I23/240,0) -> 41 | K23: =I23/30 -> 322
A24: Чугун пустоты | B24: =C24 -> 130 | C24: =SUMIF('Хср персы'!G:G,A24,'Хср персы'!F:F) -> 130 | D24: =C24-B24 -> 0 | E24: =IF(MOD(D24,5)=0,D24/5,INT(D24/5)+1) -> 0 | F24: =E24*30 -> 0 | G24: =SUM($F$2:F24) -> 7500 | H24: =E24*5-D24 -> 0
A25: Электрическая корона тени прошлого | B25: =C25 -> 76 | C25: =SUMIF('Хср персы'!G:G,A25,'Хср персы'!F:F) -> 76 | D25: =C25-B25 -> 0 | E25: =IF(MOD(D25,5)=0,D25/5,INT(D25/5)+1) -> 0 | F25: =E25*30 -> 0 | G25: =SUM($F$2:F25) -> 7500 | H25: =E25*5-D25 -> 0
A26: Электрический посох оборотня | B26: 0 | C26: =SUMIF('Хср персы'!G:G,A26,'Хср персы'!F:F) -> 195 | D26: =C26-B26 -> 195 | E26: =IF(MOD(D26,5)=0,D26/5,INT(D26/5)+1) -> 39 | F26: =E26*30 -> 1170 | G26: =SUM($F$2:F26) -> 8670 | H26: =E26*5-D26 -> 0
A27: Эндотермический хитин | B27: 0 | C27: =SUMIF('Хср персы'!G:G,A27,'Хср персы'!F:F) -> 161 | D27: =C27-B27 -> 161 | E27: =IF(MOD(D27,5)=0,D27/5,INT(D27/5)+1) -> 33 | F27: =E27*30 -> 990 | G27: =SUM($F$2:F27) -> 9660 | H27: =E27*5-D27 -> 4
G28: =SUM($F$2:F27) -> 9660 | H28: =E28*5-D28 -> 0 | I28: =SUM(E:E) -> 322

Sheet боссы следов
A2: Взгляд на сумерки | B2: =SUMIF('Хср персы'!J:J,A2,'Хср персы'!F:F) -> 195
A3: Дань вежливости | B3: =SUMIF('Хср персы'!J:J,A3,'Хср персы'!F:F) -> 325
A4: Конец мерзлоты | B4: =SUMIF('Хср персы'!J:J,A4,'Хср персы'!F:F) -> 447
A5: Начало разрушения | B5: =SUMIF('Хср персы'!J:J,A5,'Хср персы'!F:F) -> 474
A6: Поле битвы | B6: =SUMIF('Хср персы'!J:J,A6,'Хср персы'!F:F) -> 195
A7: Семя бессмертия | B7: =SUMIF('Хср персы'!J:J,A7,'Хср персы'!F:F) -> 891
A8: Старые кошмары | B8: =SUMIF('Хср персы'!J:J,A8,'Хср персы'!F:F) -> 240

Sheet ch материалы

Sheet геншин персы
A1: имя | B1: редкость | C1: регион | D1: стихия | E1: возвышение | F1: талант 1 | G1: талант 2 | H1: талант 3 | I1: кристал 5* | J1: кристал 4* | K1: кристал 3* | L1: кристал 2* | M1: количество | N1: материал босса | O1: 3* | P1: 2* | Q1: 1* | R1: материал прокачки | S1: количество | T1: материал еженедельного босса | U1: короны | V1: 4* | W1: 3* | X1: 2* | Y1: книга талантов | Z1: количество | AA1: диковинка | AB1: кки
A2: Аяка | B2: 5 | C2: Инадзума | D2: Крио | E2: 0 | F2: 0 | G2: 0 | H2: 0 | I2: =IF(E2=6,0,6) -> 6 | J2: =IF(E2=0,9,IF(E2=1,9,IF(E2=2,9,IF(E2=3,9,IF(E2=4,6,0))))) -> 9 | K2: =IF(E2=0,9,IF(E2=1,9,IF(E2=2,6,0))) -> 9 | L2: =IF(E2=0,1,0) -> 1 | M2: =IF(E2=0,46,IF(E2=1,46,IF(E2=2,44,IF(E2=3,40,IF(E2=4,32,IF(E2=5,20,0)))))) -> 46 | N2: Сердце бесконечного механизма | O2: =IF(E2=0,36,IF(E2=1,36,IF(E2=2,36,IF(E2=3,36,IF(E2=4,36,IF(E2=5,24,0))))))+IF(F2=0,31,IF(F2=1,31,IF(F2=2,31,IF(F2=3,31,IF(F2=4,31,IF(F2=5,31,IF(F2=6,31,IF(F2=7,27,IF(F2=8,21,IF(F2=9,12,0))))))))))+IF(G2=0,31,IF(G2=1,31,IF(G2=2,31,IF(G2=3,31,IF(G2=4,31,IF(G2=5,31,IF(G2=6,31,IF(G2=7,27,IF(G2=8,21,IF(G2=9,12,0))))))))))+IF(H2=0,31,IF(H2=1,31,IF(H2=2,31,IF(H2=3,31,IF(H2=4,31,IF(H2=5,31,IF(H2=6,31,IF(H2=7,27,IF(H2=8,21,IF(H2=9,12,0)))))))))) -> 129 | P2: =IF(E2=0,30,IF(E2=1,30,IF(E2=2,30,IF(E2=3,18,0))))+IF(F2=0,22,IF(F2=1,22,IF(F2=2,22,IF(F2=3,19,IF(F2=4,15,IF(F2=5,9,0))))))+IF(G2=0,31,IF(G2=1,31,IF(G2=2,31,IF(G2=3,31,IF(G2=4,31,IF(G2=5,31,0))))))+IF(H2=0,22,IF(H2=1,22,IF(H2=2,22,IF(H2=3,19,IF(H2=4,15,IF(H2=5,9,0)))))) -> 105 | Q2: =IF(E2=0,18,IF(E2=1,15,0))+IF(F2=0,6,IF(F2=1,6,0))+IF(G2=0,6,IF(G2=1,6,0))+IF(H2=0,6,IF(H2=1,6,0)) -> 36 | R2: Гарда кагэути | S2: =IF(F2=0,6,IF(F2=1,6,IF(F2=2,6,IF(F2=3,6,IF(F2=4,6,IF(F2=5,6,IF(F2=6,6,IF(F2=7,5,IF(F2=8,4,IF(F2=9,2,0))))))))))+IF(G2=0,6,IF(G2=1,6,IF(G2=2,6,IF(G2=3,6,IF(G2=4,6,IF(G2=5,6,IF(G2=6,6,IF(G2=7,5,IF(G2=8,4,IF(G2=9,2,0))))))))))+IF(H2=0,6,IF(H2=1,6,IF(H2=2,6,IF(H2=3,6,IF(H2=4,6,IF(H2=5,6,IF(H2=6,6,IF(H2=7,5,IF(H2=8,4,IF(H2=9,2,0)))))))))) -> 18 | T2: Ветвь кровавой яшмы | U2: =IF(F2=10,0,1)+IF(G2=10,0,1)+IF(H2=10,0,1) -> 3 | V2: =IF(F2=0,38,IF(F2=1,38,IF(F2=2,38,IF(F2=3,38,IF(F2=4,38,IF(F2=5,38,IF(F2=6,38,IF(F2=7,34,IF(F2=8,28,IF(F2=9,16,0))))))))))+IF(G2=0,38,IF(G2=1,38,IF(G2=2,38,IF(G2=3,38,IF(G2=4,38,IF(G2=5,38,IF(G2=6,38,IF(G2=7,34,IF(G2=8,28,IF(G2=9,16,0))))))))))+IF(H2=0,38,IF(H2=1,38,IF(H2=2,38,IF(H2=3,38,IF(H2=4,38,IF(H2=5,38,IF(H2=6,38,IF(H2=7,34,IF(H2=8,28,IF(H2=9,16,0)))))))))) -> 114 | W2: =IF(F2=0,21,IF(F2=1,21,IF(F2=2,21,IF(F2=3,19,IF(F2=4,15,IF(F2=5,9,0))))))+IF(G2=0,21,IF(G2=1,21,IF(G2=2,21,IF(G2=3,19,IF(G2=4,15,IF(G2=5,21,0))))))+IF(H2=0,21,IF(H2=1,21,IF(H2=2,21,IF(H2=3,19,IF(H2=4,15,IF(H2=5,9,0)))))) -> 63 | X2: =IF(F2=0,3,IF(F2=1,3,0))+IF(G2=0,3,IF(G2=1,3,0))+IF(H2=0,3,IF(H2=1,3,0)) -> 9 | Y2: Изящество | Z2: =IF(E2=0,168,IF(E2=1,165,IF(E2=2,155,IF(E2=3,135,IF(E2=4,105,IF(E2=5,60,0)))))) -> 168 | AA2: Сакура | AB2: 1
A3: Аято | B3: 5 | C3: Инадзума | D3: Гидро | E3: 6 | F3: 8 | G3: 10 | H3: 9 | I3: =IF(E3=6,0,6) -> 0 | J3: =IF(E3=0,9,IF(E3=1,9,IF(E3=2,9,IF(E3=3,9,IF(E3=4,6,0))))) -> 0 | K3: =IF(E3=0,9,IF(E3=1,9,IF(E3=2,6,0))) -> 0 | L3: =IF(E3=0,1,0) -> 0 | M3: =IF(E3=0,46,IF(E3=1,46,IF(E3=2,44,IF(E3=3,40,IF(E3=4,32,IF(E3=5,20,0)))))) -> 0 | N3: Роса отречения | O3: =IF(E3=0,36,IF(E3=1,36,IF(E3=2,36,IF(E3=3,36,IF(E3=4,36,IF(E3=5,24,0))))))+IF(F3=0,31,IF(F3=1,31,IF(F3=2,31,IF(F3=3,31,IF(F3=4,31,IF(F3=5,31,IF(F3=6,31,IF(F3=7,27,IF(F3=8,21,IF(F3=9,12,0))))))))))+IF(G3=0,31,IF(G3=1,31,IF(G3=2,31,IF(G3=3,31,IF(G3=4,31,IF(G3=5,31,IF(G3=6,31,IF(G3=7,27,IF(G3=8,21,IF(G3=9,12,0))))))))))+IF(H3=0,31,IF(H3=1,31,IF(H3=2,31,IF(H3=3,31,IF(H3=4,31,IF(H3=5,31,IF(H3=6,31,IF(H3=7,27,IF(H3=8,21,IF(H3=9,12,0)))))))))) -> 33 | P3: =IF(E3=0,30,IF(E3=1,30,IF(E3=2,30,IF(E3=3,18,0))))+IF(F3=0,22,IF(F3=1,22,IF(F3=2,22,IF(F3=3,19,IF(F3=4,15,IF(F3=5,9,0))))))+IF(G3=0,31,IF(G3=1,31,IF(G3=2,31,IF(G3=3,31,IF(G3=4,31,IF(G3=5,31,0))))))+IF(H3=0,22,IF(H3=1,22,IF(H3=2,22,IF(H3=3,19,IF(H3=4,15,IF(H3=5,9,0)))))) -> 0 | Q3: =IF(E3=0,18,IF(E3=1,15,0))+IF(F3=0,6,IF(F3=1,6,0))+IF(G3=0,6,IF(G3=1,6,0))+IF(H3=0,6,IF(H3=1,6,0)) -> 0 | R3: Гарда кагэути | S3: =IF(F3=0,6,IF(F3=1,6,IF(F3=2,6,IF(F3=3,6,IF(F3=4,6,IF(F3=5,6,IF(F3=6,6,IF(F3=7,5,IF(F3=8,4,IF(F3=9,2,0))))))))))+IF(G3=0,6,IF(G3=1,6,IF(G3=2,6,IF(G3=3,6,IF(G3=4,6,IF(G3=5,6,IF(G3=6,6,IF(G3=7,5,IF(G3=8,4,IF(G3=9,2,0))))))))))+IF(H3=0,6,IF(H3=1,6,IF(H3=2,6,IF(H3=3,6,IF(H3=4,6,IF(H3=5,6,IF(H3=6,6,IF(H3=7,5,IF(H3=8,4,IF(H3=9,2,0)))))))))) -> 6 | T3: Мудра зловещего генерала | U3: =IF(F3=10,0,1)+IF(G3=10,0,1)+IF(H3=10,0,1) -> 2 | V3: =IF(F3=0,38,IF(F3=1,38,IF(F3=2,38,IF(F3=3,38,IF(F3=4,38,IF(F3=5,38,IF(F3=6,38,IF(F3=7,34,IF(F3=8,28,IF(F3=9,16,0))))))))))+IF(G3=0,38,IF(G3=1,38,IF(G3=2,38,IF(G3=3,38,IF(G3=4,38,IF(G3=5,38,IF(G3=6,38,IF(G3=7,34,IF(G3=8,28,IF(G3=9,16,0))))))))))+IF(H3=0,38,IF(H3=1,38,IF(H3=2,38,IF(H3=3,38,IF(H3=4,38,IF(H3=5,38,IF(H3=6,38,IF(H3=7,34,IF(H3=8,28,IF(H3=9,16,0)))))))))) -> 44 | W3: =IF(F3=0,21,IF(F3=1,21,IF(F3=2,21,IF(F3=3,19,IF(F3=4,15,IF(F3=5,9,0))))))+IF(G3=0,21,IF(G3=1,21,IF(G3=2,21,IF(G3=3,19,IF(G3=4,15,IF(G3=5,21,0))))))+IF(H3=0,21,IF(H3=1,21,IF(H3=2,21,IF(H3=3,19,IF(H3=4,15,IF(H3=5,9,0)))))) -> 0 | X3: =IF(F3=0,3,IF(F3=1,3,0))+IF(G3=0,3,IF(G3=1,3,0))+IF(H3=0,3,IF(H3=1,3,0)) -> 0 | Y3: Изящество | Z3: =IF(E3=0,168,IF(E3=1,165,IF(E3=2,155,IF(E3=3,135,IF(E3=4,105,IF(E3=5,60,0)))))) -> 0 | AA3: Сакура | AB3: 1
A4: Еимия | B4: 5 | C4: Инадзума | D4: Пиро | E4: 5 | F4: 8 | G4: 8 | H4: 1 | I4: =IF(E4=6,0,6) -> 6 | J4: =IF(E4=0,9,IF(E4=1,9,IF(E4=2,9,IF(E4=3,9,IF(E4=4,6,0))))) -> 0 | K4: =IF(E4=0,9,IF(E4=1,9,IF(E4=2,6,0))) -> 0 | L4: =IF(E4=0,1,0) -> 0 | M4: =IF(E4=0,46,IF(E4=1,46,IF(E4=2,44,IF(E4=3,40,IF(E4=4,32,IF(E4=5,20,0)))))) -> 20 | N4: Тлеющая жемчужина | O4: =IF(E4=0,36,IF(E4=1,36,IF(E4=2,36,IF(E4=3,36,IF(E4=4,36,IF(E4=5,24,0))))))+IF(F4=0,31,IF(F4=1,31,IF(F4=2,31,IF(F4=3,31,IF(F4=4,31,IF(F4=5,31,IF(F4=6,31,IF(F4=7,27,IF(F4=8,21,IF(F4=9,12,0))))))))))+IF(G4=0,31,IF(G4=1,31,IF(G4=2,31,IF(G4=3,31,IF(G4=4,31,IF(G4=5,31,IF(G4=6,31,IF(G4=7,27,IF(G4=8,21,IF(G4=9,12,0))))))))))+IF(H4=0,31,IF(H4=1,31,IF(H4=2,31,IF(H4=3,31,IF(H4=4,31,IF(H4=5,31,IF(H4=6,31,IF(H4=7,27,IF(H4=8,21,IF(H4=9,12,0)))))))))) -> 97 | P4: =IF(E4=0,30,IF(E4=1,30,IF(E4=2,30,IF(E4=3,18,0))))+IF(F4=0,22,IF(F4=1,22,IF(F4=2,22,IF(F4=3,19,IF(F4=4,15,IF(F4=5,9,0))))))+IF(G4=0,31,IF(G4=1,31,IF(G4=2,31,IF(G4=3,31,IF(G4=4,31,IF(G4=5,31,0))))))+IF(H4=0,22,IF(H4=1,22,IF(H4=2,22,IF(H4=3,19,IF(H4=4,15,IF(H4=5,9,0)))))) -> 22 | Q4: =IF(E4=0,18,IF(E4=1,15,0))+IF(F4=0,6,IF(F4=1,6,0))+IF(G4=0,6,IF(G4=1,6,0))+IF(H4=0,6,IF(H4=1,6,0)) -> 6 | R4: Свиток божественной магии | S4: =IF(F4=0,6,IF(F4=1,6,IF(F4=2,6,IF(F4=3,6,IF(F4=4,6,IF(F4=5,6,IF(F4=6,6,IF(F4=7,5,IF(F4=8,4,IF(F4=9,2,0))))))))))+IF(G4=0,6,IF(G4=1,6,IF(G4=2,6,IF(G4=3,6,IF(G4=4,6,IF(G4=5,6,IF(G4=6,6,IF(G4=7,5,IF(G4=8,4,IF(G4=9,2,0))))))))))+IF(H4=0,6,IF(H4=1,6,IF(H4=2,6,IF(H4=3,6,IF(H4=4,6,IF(H4=5,6,IF(H4=6,6,IF(H4=7,5,IF(H4=8,4,IF(H4=9,2,0)))))))))) -> 14 | T4: Корона лорда драконов | U4: =IF(F4=10,0,1)+IF(G4=10,0,1)+IF(H4=10,0,1) -> 3 | V4: =IF(F4=0,38,IF(F4=1,38,IF(F4=2,38,IF(F4=3,38,IF(F4=4,38,IF(F4=5,38,IF(F4=6,38,IF(F4=7,34,IF(F4=8,28,IF(F4=9,16,0))))))))))+IF(G4=0,38,IF(G4=1,38,IF(G4=2,38,IF(G4=3,38,IF(G4=4,38,IF(G4=5,38,IF(G4=6,38,IF(G4=7,34,IF(G4=8,28,IF(G4=9,16,0))))))))))+IF(H4=0,38,IF(H4=1,38,IF(H4=2,38,IF(H4=3,38,IF(H4=4,38,IF(H4=5,38,IF(H4=6,38,IF(H4=7,34,IF(H4=8,28,IF(H4=9,16,0)))))))))) -> 94 | W4: =IF(F4=0,21,IF(F4=1,21,IF(F4=2,21,IF(F4=3,19,IF(F4=4,15,IF(F4=5,9,0))))))+IF(G4=0,21,IF(G4=1,21,IF(G4=2,21,IF(G4=3,19,IF(G4=4,15,IF(G4=5,21,0))))))+IF(H4=0,21,IF(H4=1,21,IF(H4=2,21,IF(H4=3,19,IF(H4=4,15,IF(H4=5,9,0)))))) -> 21 | X4: =IF(F4=0,3,IF(F4=1,3,0))+IF(G4=0,3,IF(G4=1,3,0))+IF(H4=0,3,IF(H4=1,3,0)) -> 3 | Y4: Бренность | Z4: =IF(E4=0,168,IF(E4=1,165,IF(E4=2,155,IF(E4=3,135,IF(E4=4,105,IF(E4=5,60,0)))))) -> 60 | AA4: Трава наку | AB4: 1
A5: Итто | B5: 5 | C5: Инадзума | D5: Гео | E5: 0 | F5: 0 | G5: 0 | H5: 0 | I5: =IF(E5=6,0,6) -> 6 | J5: =IF(E5=0,9,IF(E5=1,9,IF(E5=2,9,IF(E5=3,9,IF(E5=4,6,0))))) -> 9 | K5: =IF(E5=0,9,IF(E5=1,9,IF(E5=2,6,0))) -> 9 | L5: =IF(E5=0,1,0) -> 1 | M5: =IF(E5=0,46,IF(E5=1,46,IF(E5=2,44,IF(E5=3,40,IF(E5=4,32,IF(E5=5,20,0)))))) -> 46 | N5: Эмблема Разрыва | O5: =IF(E5=0,36,IF(E5=1,36,IF(E5=2,36,IF(E5=3,36,IF(E5=4,36,IF(E5=5,24,0))))))+IF(F5=0,31,IF(F5=1,31,IF(F5=2,31,IF(F5=3,31,IF(F5=4,31,IF(F5=5,31,IF(F5=6,31,IF(F5=7,27,IF(F5=8,21,IF(F5=9,12,0))))))))))+IF(G5=0,31,IF(G5=1,31,IF(G5=2,31,IF(G5=3,31,IF(G5=4,31,IF(G5=5,31,IF(G5=6,31,IF(G5=7,27,IF(G5=8,21,IF(G5=9,12,0))))))))))+IF(H5=0,31,IF(H5=1,31,IF(H5=2,31,IF(H5=3,31,IF(H5=4,31,IF(H5=5,31,IF(H5=6,31,IF(H5=7,27,IF(H5=8,21,IF(H5=9,12,0)))))))))) -> 129 | P5: =IF(E5=0,30,IF(E5=1,30,IF(E5=2,30,IF(E5=3,18,0))))+IF(F5=0,22,IF(F5=1,22,IF(F5=2,22,IF(F5=3,19,IF(F5=4,15,IF(F5=5,9,0))))))+IF(G5=0,31,IF(G5=1,31,IF(G5=2,31,IF(G5=3,31,IF(G5=4,31,IF(G5=5,31,0))))))+IF(H5=0,22,IF(H5=1,22,IF(H5=2,22,IF(H5=3,19,IF(H5=4,15,IF(H5=5,9,0)))))) -> 105 | Q5: =IF(E5=0,18,IF(E5=1,15,0))+IF(F5=0,6,IF(F5=1,6,0))+IF(G5=0,6,IF(G5=1,6,0))+IF(H5=0,6,IF(H5=1,6,0)) -> 36 | R5: Слизь слайма | S5: =IF(F5=0,6,IF(F5=1,6,IF(F5=2,6,IF(F5=3,6,IF(F5=4,6,IF(F5=5,6,IF(F5=6,6,IF(F5=7,5,IF(F5=8,4,IF(F5=9,2,0))))))))))+IF(G5=0,6,IF(G5=1,6,IF(G5=2,6,IF(G5=3,6,IF(G5=4,6,IF(G5=5,6,IF(G5=6,6,IF(G5=7,5,IF(G5=8,4,IF(G5=9,2,0))))))))))+IF(H5=0,6,IF(H5=1,6,IF(H5=2,6,IF(H5=3,6,IF(H5=4,6,IF(H5=5,6,IF(H5=6,6,IF(H5=7,5,IF(H5=8,4,IF(H5=9,2,0)))))))))) -> 18 | T5: Пепельное сердце | U5: =IF(F5=10,0,1)+IF(G5=10,0,1)+IF(H5=10,0,1) -> 3 | V5: =IF(F5=0,38,IF(F5=1,38,IF(F5=2,38,IF(F5=3,38,IF(F5=4,38,IF(F5=5,38,IF(F5=6,38,IF(F5=7,34,IF(F5=8,28,IF(F5=9,16,0))))))))))+IF(G5=0,38,IF(G5=1,38,IF(G5=2,38,IF(G5=3,38,IF(G5=4,38,IF(G5=5,38,IF(G5=6,38,IF(G5=7,34,IF(G5=8,28,IF(G5=9,16,0))))))))))+IF(H5=0,38,IF(H5=1,38,IF(H5=2,38,IF(H5=3,38,IF(H5=4,38,IF(H5=5,38,IF(H5=6,38,IF(H5=7,34,IF(H5=8,28,IF(H5=9,16,0)))))))))) -> 114 | W5: =IF(F5=0,21,IF(F5=1,21,IF(F5=2,21,IF(F5=3,19,IF(F5=4,15,IF(F5=5,9,0))))))+IF(G5=0,21,IF(G5=1,21,IF(G5=2,21,IF(G5=3,19,IF(G5=4,15,IF(G5=5,21,0))))))+IF(H5=0,21,IF(H5=1,21,IF(H5=2,21,IF(H5=3,19,IF(H5=4,15,IF(H5=5,9,0)))))) -> 63 | X5: =IF(F5=0,3,IF(F5=1,3,0))+IF(G5=0,3,IF(G5=1,3,0))+IF(H5=0,3,IF(H5=1,3,0)) -> 9 | Y5: Изящество | Z5: =IF(E5=0,168,IF(E5=1,165,IF(E5=2,155,IF(E5=3,135,IF(E5=4,105,IF(E5=5,60,0)))))) -> 168 | AA5: Оникабуто | AB5: 1
A6: Кокоми | B6: 5 | C6: Инадзума | D6: Гидро | E6: 0 | F6: 0 | G6: 0 | H6: 0 | I6: =IF(E6=6,0,6) -> 6 | J6: =IF(E6=0,9,IF(E6=1,9,IF(E6=2,9,IF(E6=3,9,IF(E6=4,6,0))))) -> 9 | K6: =IF(E6=0,9,IF(E6=1,9,IF(E6=2,6,0))) -> 9 | L6: =IF(E6=0,1,0) -> 1 | M6: =IF(E6=0,46,IF(E6=1,46,IF(E6=2,44,IF(E6=3,40,IF(E6=4,32,IF(E6=5,20,0)))))) -> 46 | N6: Роса отречения | O6: =IF(E6=0,36,IF(E6=1,36,IF(E6=2,36,IF(E6=3,36,IF(E6=4,36,IF(E6=5,24,0))))))+IF(F6=0,31,IF(F6=1,31,IF(F6=2,31,IF(F6=3,31,IF(F6=4,31,IF(F6=5,31,IF(F6=6,31,IF(F6=7,27,IF(F6=8,21,IF(F6=9,12,0))))))))))+IF(G6=0,31,IF(G6=1,31,IF(G6=2,31,IF(G6=3,31,IF(G6=4,31,IF(G6=5,31,IF(G6=6,31,IF(G6=7,27,IF(G6=8,21,IF(G6=9,12,0))))))))))+IF(H6=0,31,IF(H6=1,31,IF(H6=2,31,IF(H6=3,31,IF(H6=4,31,IF(H6=5,31,IF(H6=6,31,IF(H6=7,27,IF(H6=8,21,IF(H6=9,12,0)))))))))) -> 129 | P6: =IF(E6=0,30,IF(E6=1,30,IF(E6=2,30,IF(E6=3,18,0))))+IF(F6=0,22,IF(F6=1,22,IF(F6=2,22,IF(F6=3,19,IF(F6=4,15,IF(F6=5,9,0))))))+IF(G6=0,31,IF(G6=1,31,IF(G6=2,31,IF(G6=3,31,IF(G6=4,31,IF(G6=5,31,0))))))+IF(H6=0,22,IF(H6=1,22,IF(H6=2,22,IF(H6=3,19,IF(H6=4,15,IF(H6=5,9,0)))))) -> 105 | Q6: =IF(E6=0,18,IF(E6=1,15,0))+IF(F6=0,6,IF(F6=1,6,0))+IF(G6=0,6,IF(G6=1,6,0))+IF(H6=0,6,IF(H6=1,6,0)) -> 36 | R6: Призрачная оболочка | S6: =IF(F6=0,6,IF(F6=1,6,IF(F6=2,6,IF(F6=3,6,IF(F6=4,6,IF(F6=5,6,IF(F6=6,6,IF(F6=7,5,IF(F6=8,4,IF(F6=9,2,0))))))))))+IF(G6=0,6,IF(G6=1,6,IF(G6=2,6,IF(G6=3,6,IF(G6=4,6,IF(G6=5,6,IF(G6=6,6,IF(G6=7,5,IF(G6=8,4,IF(G6=9,2,0))))))))))+IF(H6=0,6,IF(H6=1,6,IF(H6=2,6,IF(H6=3,6,IF(H6=4,6,IF(H6=5,6,IF(H6=6,6,IF(H6=7,5,IF(H6=8,4,IF(H6=9,2,0)))))))))) -> 18 | T6: Бабочка адского пламени | U6: =IF(F6=10,0,1)+IF(G6=10,0,1)+IF(H6=10,0,1) -> 3 | V6: =IF(F6=0,38,IF(F6=1,38,IF(F6=2,38,IF(F6=3,38,IF(F6=4,38,IF(F6=5,38,IF(F6=6,38,IF(F6=7,34,IF(F6=8,28,IF(F6=9,16,0))))))))))+IF(G6=0,38,IF(G6=1,38,IF(G6=2,38,IF(G6=3,38,IF(G6=4,38,IF(G6=5,38,IF(G6=6,38,IF(G6=7,34,IF(G6=8,28,IF(G6=9,16,0))))))))))+IF(H6=0,38,IF(H6=1,38,IF(H6=2,38,IF(H6=3,38,IF(H6=4,38,IF(H6=5,38,IF(H6=6,38,IF(H6=7,34,IF(H6=8,28,IF(H6=9,16,0)))))))))) -> 114 | W6: =IF(F6=0,21,IF(F6=1,21,IF(F6=2,21,IF(F6=3,19,IF(F6=4,15,IF(F6=5,9,0))))))+IF(G6=0,21,IF(G6=1,21,IF(G6=2,21,IF(G6=3,19,IF(G6=4,15,IF(G6=5,21,0))))))+IF(H6=0,21,IF(H6=1,21,IF(H6=2,21,IF(H6=3,19,IF(H6=4,15,IF(H6=5,9,0)))))) -> 63 | X6: =IF(F6=0,3,IF(F6=1,3,0))+IF(G6=0,3,IF(G6=1,3,0))+IF(H6=0,3,IF(H6=1,3,0)) -> 9 | Y6: Бренность | Z6: =IF(E6=0,168,IF(E6=1,165,IF(E6=2,155,IF(E6=3,135,IF(E6=4,105,IF(E6=5,60,0)))))) -> 168 | AA6: Жемчужина Санго | AB6: 1
A7: Райдэн | B7: 5 | C7: Инадзума | D7: Электро | E7: 6 | F7: 2 | G7: 9 | H7: 10 | I7: =IF(E7=6,0,6) -> 0 | J7: =IF(E7=0,9,IF(E7=1,9,IF(E7=2,9,IF(E7=3,9,IF(E7=4,6,0))))) -> 0 | K7: =IF(E7=0,9,IF(E7=1,9,IF(E7=2,6,0))) -> 0 | L7: =IF(E7=0,1,0) -> 0 | M7: =IF(E7=0,46,IF(E7=1,46,IF(E7=2,44,IF(E7=3,40,IF(E7=4,32,IF(E7=5,20,0)))))) -> 0 | N7: Штормовой жемчуг | O7: =IF(E7=0,36,IF(E7=1,36,IF(E7=2,36,IF(E7=3,36,IF(E7=4,36,IF(E7=5,24,0))))))+IF(F7=0,31,IF(F7=1,31,IF(F7=2,31,IF(F7=3,31,IF(F7=4,31,IF(F7=5,31,IF(F7=6,31,IF(F7=7,27,IF(F7=8,21,IF(F7=9,12,0))))))))))+IF(G7=0,31,IF(G7=1,31,IF(G7=2,31,IF(G7=3,31,IF(G7=4,31,IF(G7=5,31,IF(G7=6,31,IF(G7=7,27,IF(G7=8,21,IF(G7=9,12,0))))))))))+IF(H7=0,31,IF(H7=1,31,IF(H7=2,31,IF(H7=3,31,IF(H7=4,31,IF(H7=5,31,IF(H7=6,31,IF(H7=7,27,IF(H7=8,21,IF(H7=9,12,0)))))))))) -> 43 | P7: =IF(E7=0,30,IF(E7=1,30,IF(E7=2,30,IF(E7=3,18,0))))+IF(F7=0,22,IF(F7=1,22,IF(F7=2,22,IF(F7=3,19,IF(F7=4,15,IF(F7=5,9,0))))))+IF(G7=0,31,IF(G7=1,31,IF(G7=2,31,IF(G7=3,31,IF(G7=4,31,IF(G7=5,31,0))))))+IF(H7=0,22,IF(H7=1,22,IF(H7=2,22,IF(H7=3,19,IF(H7=4,15,IF(H7=5,9,0)))))) -> 22 | Q7: =IF(E7=0,18,IF(E7=1,15,0))+IF(F7=0,6,IF(F7=1,6,0))+IF(G7=0,6,IF(G7=1,6,0))+IF(H7=0,6,IF(H7=1,6,0)) -> 0 | R7: Гарда кагэути | S7: =IF(F7=0,6,IF(F7=1,6,IF(F7=2,6,IF(F7=3,6,IF(F7=4,6,IF(F7=5,6,IF(F7=6,6,IF(F7=7,5,IF(F7=8,4,IF(F7=9,2,0))))))))))+IF(G7=0,6,IF(G7=1,6,IF(G7=2,6,IF(G7=3,6,IF(G7=4,6,IF(G7=5,6,IF(G7=6,6,IF(G7=7,5,IF(G7=8,4,IF(G7=9,2,0))))))))))+IF(H7=0,6,IF(H7=1,6,IF(H7=2,6,IF(H7=3,6,IF(H7=4,6,IF(H7=5,6,IF(H7=6,6,IF(H7=7,5,IF(H7=8,4,IF(H7=9,2,0)))))))))) -> 8 | T7: Расплавленный миг | U7: =IF(F7=10,0,1)+IF(G7=10,0,1)+IF(H7=10,0,1) -> 2 | V7: =IF(F7=0,38,IF(F7=1,38,IF(F7=2,38,IF(F7=3,38,IF(F7=4,38,IF(F7=5,38,IF(F7=6,38,IF(F7=7,34,IF(F7=8,28,IF(F7=9,16,0))))))))))+IF(G7=0,38,IF(G7=1,38,IF(G7=2,38,IF(G7=3,38,IF(G7=4,38,IF(G7=5,38,IF(G7=6,38,IF(G7=7,34,IF(G7=8,28,IF(G7=9,16,0))))))))))+IF(H7=0,38,IF(H7=1,38,IF(H7=2,38,IF(H7=3,38,IF(H7=4,38,IF(H7=5,38,IF(H7=6,38,IF(H7=7,34,IF(H7=8,28,IF(H7=9,16,0)))))))))) -> 54 | W7: =IF(F7=0,21,IF(F7=1,21,IF(F7=2,21,IF(F7=3,19,IF(F7=4,15,IF(F7=5,9,0))))))+IF(G7=0,21,IF(G7=1,21,IF(G7=2,21,IF(G7=3,19,IF(G7=4,15,IF(G7=5,21,0))))))+IF(H7=0,21,IF(H7=1,21,IF(H7=2,21,IF(H7=3,19,IF(H7=4,15,IF(H7=5,9,0)))))) -> 21 | X7: =IF(F7=0,3,IF(F7=1,3,0))+IF(G7=0,3,IF(G7=1,3,0))+IF(H7=0,3,IF(H7=1,3,0)) -> 0 | Y7: Свет | Z7: =IF(E7=0,168,IF(E7=1,165,IF(E7=2,155,IF(E7=3,135,IF(E7=4,105,IF(E7=5,60,0)))))) -> 0 | AA7: Плод облачной травы | AB7: 1
A8: Яэ Мико | B8: 5 | C8: Инадзума | D8: Электро | E8: 6 | F8: 1 | G8: 9 | H8: 1 | I8: =IF(E8=6,0,6) -> 0 | J8: =IF(E8=0,9,IF(E8=1,9,IF(E8=2,9,IF(E8=3,9,IF(E8=4,6,0))))) -> 0 | K8: =IF(E8=0,9,IF(E8=1,9,IF(E8=2,6,0))) -> 0 | L8: =IF(E8=0,1,0) -> 0 | M8: =IF(E8=0,46,IF(E8=1,46,IF(E8=2,44,IF(E8=3,40,IF(E8=4,32,IF(E8=5,20,0)))))) -> 0 | N8: Ложный плавник Дракона глубин | O8: =IF(E8=0,36,IF(E8=1,36,IF(E8=2,36,IF(E8=3,36,IF(E8=4,36,IF(E8=5,24,0))))))+IF(F8=0,31,IF(F8=1,31,IF(F8=2,31,IF(F8=3,31,IF(F8=4,31,IF(F8=5,31,IF(F8=6,31,IF(F8=7,27,IF(F8=8,21,IF(F8=9,12,0))))))))))+IF(G8=0,31,IF(G8=1,31,IF(G8=2,31,IF(G8=3,31,IF(G8=4,31,IF(G8=5,31,IF(G8=6,31,IF(G8=7,27,IF(G8=8,21,IF(G8=9,12,0))))))))))+IF(H8=0,31,IF(H8=1,31,IF(H8=2,31,IF(H8=3,31,IF(H8=4,31,IF(H8=5,31,IF(H8=6,31,IF(H8=7,27,IF(H8=8,21,IF(H8=9,12,0)))))))))) -> 74 | P8: =IF(E8=0,30,IF(E8=1,30,IF(E8=2,30,IF(E8=3,18,0))))+IF(F8=0,22,IF(F8=1,22,IF(F8=2,22,IF(F8=3,19,IF(F8=4,15,IF(F8=5,9,0))))))+IF(G8=0,31,IF(G8=1,31,IF(G8=2,31,IF(G8=3,31,IF(G8=4,31,IF(G8=5,31,0))))))+IF(H8=0,22,IF(H8=1,22,IF(H8=2,22,IF(H8=3,19,IF(H8=4,15,IF(H8=5,9,0)))))) -> 44 | Q8: =IF(E8=0,18,IF(E8=1,15,0))+IF(F8=0,6,IF(F8=1,6,0))+IF(G8=0,6,IF(G8=1,6,0))+IF(H8=0,6,IF(H8=1,6,0)) -> 12 | R8: Гарда кагэути | S8: =IF(F8=0,6,IF(F8=1,6,IF(F8=2,6,IF(F8=3,6,IF(F8=4,6,IF(F8=5,6,IF(F8=6,6,IF(F8=7,5,IF(F8=8,4,IF(F8=9,2,0))))))))))+IF(G8=0,6,IF(G8=1,6,IF(G8=2,6,IF(G8=3,6,IF(G8=4,6,IF(G8=5,6,IF(G8=6,6,IF(G8=7,5,IF(G8=8,4,IF(G8=9,2,0))))))))))+IF(H8=0,6,IF(H8=1,6,IF(H8=2,6,IF(H8=3,6,IF(H8=4,6,IF(H8=5,6,IF(H8=6,6,IF(H8=7,5,IF(H8=8,4,IF(H8=9,2,0)))))))))) -> 14 | T8: Смысл эонов | U8: =IF(F8=10,0,1)+IF(G8=10,0,1)+IF(H8=10,0,1) -> 3 | V8: =IF(F8=0,38,IF(F8=1,38,IF(F8=2,38,IF(F8=3,38,IF(F8=4,38,IF(F8=5,38,IF(F8=6,38,IF(F8=7,34,IF(F8=8,28,IF(F8=9,16,0))))))))))+IF(G8=0,38,IF(G8=1,38,IF(G8=2,38,IF(G8=3,38,IF(G8=4,38,IF(G8=5,38,IF(G8=6,38,IF(G8=7,34,IF(G8=8,28,IF(G8=9,16,0))))))))))+IF(H8=0,38,IF(H8=1,38,IF(H8=2,38,IF(H8=3,38,IF(H8=4,38,IF(H8=5,38,IF(H8=6,38,IF(H8=7,34,IF(H8=8,28,IF(H8=9,16,0)))))))))) -> 92 | W8: =IF(F8=0,21,IF(F8=1,21,IF(F8=2,21,IF(F8=3,19,IF(F8=4,15,IF(F8=5,9,0))))))+IF(G8=0,21,IF(G8=1,21,IF(G8=2,21,IF(G8=3,19,IF(G8=4,15,IF(G8=5,21,0))))))+IF(H8=0,21,IF(H8=1,21,IF(H8=2,21,IF(H8=3,19,IF(H8=4,15,IF(H8=5,9,0)))))) -> 42 | X8: =IF(F8=0,3,IF(F8=1,3,0))+IF(G8=0,3,IF(G8=1,3,0))+IF(H8=0,3,IF(H8=1,3,0)) -> 6 | Y8: Свет | Z8: =IF(E8=0,168,IF(E8=1,165,IF(E8=2,155,IF(E8=3,135,IF(E8=4,105,IF(E8=5,60,0)))))) -> 0 | AA8: Морской гриб | AB8: 1
A9: Горо | B9: 4 | C9: Инадзума | D9: Гео | E9: 3 | F9: 1 | G9: 1 | H9: 2 | I9: =IF(E9=6,0,6) -> 6 | J9: =IF(E9=0,9,IF(E9=1,9,IF(E9=2,9,IF(E9=3,9,IF(E9=4,6,0))))) -> 9 | K9: =IF(E9=0,9,IF(E9=1,9,IF(E9=2,6,0))) -> 0 | L9: =IF(E9=0,1,0) -> 0 | M9: =IF(E9=0,46,IF(E9=1,46,IF(E9=2,44,IF(E9=3,40,IF(E9=4,32,IF(E9=5,20,0)))))) -> 40 | N9: Сердце бесконечного механизма | O9: =IF(E9=0,36,IF(E9=1,36,IF(E9=2,36,IF(E9=3,36,IF(E9=4,36,IF(E9=5,24,0))))))+IF(F9=0,31,IF(F9=1,31,IF(F9=2,31,IF(F9=3,31,IF(F9=4,31,IF(F9=5,31,IF(F9=6,31,IF(F9=7,27,IF(F9=8,21,IF(F9=9,12,0))))))))))+IF(G9=0,31,IF(G9=1,31,IF(G9=2,31,IF(G9=3,31,IF(G9=4,31,IF(G9=5,31,IF(G9=6,31,IF(G9=7,27,IF(G9=8,21,IF(G9=9,12,0))))))))))+IF(H9=0,31,IF(H9=1,31,IF(H9=2,31,IF(H9=3,31,IF(H9=4,31,IF(H9=5,31,IF(H9=6,31,IF(H9=7,27,IF(H9=8,21,IF(H9=9,12,0)))))))))) -> 129 | P9: =IF(E9=0,30,IF(E9=1,30,IF(E9=2,30,IF(E9=3,18,0))))+IF(F9=0,22,IF(F9=1,22,IF(F9=2,22,IF(F9=3,19,IF(F9=4,15,IF(F9=5,9,0))))))+IF(G9=0,31,IF(G9=1,31,IF(G9=2,31,IF(G9=3,31,IF(G9=4,31,IF(G9=5,31,0))))))+IF(H9=0,22,IF(H9=1,22,IF(H9=2,22,IF(H9=3,19,IF(H9=4,15,IF(H9=5,9,0)))))) -> 93 | Q9: =IF(E9=0,18,IF(E9=1,15,0))+IF(F9=0,6,IF(F9=1,6,0))+IF(G9=0,6,IF(G9=1,6,0))+IF(H9=0,6,IF(H9=1,6,0)) -> 12 | R9: Призрачная оболочка | S9: =IF(F9=0,6,IF(F9=1,6,IF(F9=2,6,IF(F9=3,6,IF(F9=4,6,IF(F9=5,6,IF(F9=6,6,IF(F9=7,5,IF(F9=8,4,IF(F9=9,2,0))))))))))+IF(G9=0,6,IF(G9=1,6,IF(G9=2,6,IF(G9=3,6,IF(G9=4,6,IF(G9=5,6,IF(G9=6,6,IF(G9=7,5,IF(G9=8,4,IF(G9=9,2,0))))))))))+IF(H9=0,6,IF(H9=1,6,IF(H9=2,6,IF(H9=3,6,IF(H9=4,6,IF(H9=5,6,IF(H9=6,6,IF(H9=7,5,IF(H9=8,4,IF(H9=9,2,0)))))))))) -> 18 | T9: Расплавленный миг | U9: =IF(F9=10,0,1)+IF(G9=10,0,1)+IF(H9=10,0,1) -> 3 | V9: =IF(F9=0,38,IF(F9=1,38,IF(F9=2,38,IF(F9=3,38,IF(F9=4,38,IF(F9=5,38,IF(F9=6,38,IF(F9=7,34,IF(F9=8,28,IF(F9=9,16,0))))))))))+IF(G9=0,38,IF(G9=1,38,IF(G9=2,38,IF(G9=3,38,IF(G9=4,38,IF(G9=5,38,IF(G9=6,38,IF(G9=7,34,IF(G9=8,28,IF(G9=9,16,0))))))))))+IF(H9=0,38,IF(H9=1,38,IF(H9=2,38,IF(H9=3,38,IF(H9=4,38,IF(H9=5,38,IF(H9=6,38,IF(H9=7,34,IF(H9=8,28,IF(H9=9,16,0)))))))))) -> 114 | W9: =IF(F9=0,21,IF(F9=1,21,IF(F9=2,21,IF(F9=3,19,IF(F9=4,15,IF(F9=5,9,0))))))+IF(G9=0,21,IF(G9=1,21,IF(G9=2,21,IF(G9=3,19,IF(G9=4,15,IF(G9=5,21,0))))))+IF(H9=0,21,IF(H9=1,21,IF(H9=2,21,IF(H9=3,19,IF(H9=4,15,IF(H9=5,9,0)))))) -> 63 | X9: =IF(F9=0,3,IF(F9=1,3,0))+IF(G9=0,3,IF(G9=1,3,0))+IF(H9=0,3,IF(H9=1,3,0)) -> 6 | Y9: Свет | Z9: =IF(E9=0,168,IF(E9=1,165,IF(E9=2,155,IF(E9=3,135,IF(E9=4,105,IF(E9=5,60,0)))))) -> 135 | AA9: Жемчужина Санго
A10: Кирара | B10: 4 | C10: Инадзума | D10: Дендро | E10: 1 | F10: 1 | G10: 1 | H10: 1 | I10: =IF(E10=6,0,6) -> 6 | J10: =IF(E10=0,9,IF(E10=1,9,IF(E10=2,9,IF(E10=3,9,IF(E10=4,6,0))))) -> 9 | K10: =IF(E10=0,9,IF(E10=1,9,IF(E10=2,6,0))) -> 9 | L10: =IF(E10=0,1,0) -> 0 | M10: =IF(E10=0,46,IF(E10=1,46,IF(E10=2,44,IF(E10=3,40,IF(E10=4,32,IF(E10=5,20,0)))))) -> 46 | N10: Кольцо вечного мрака | O10: =IF(E10=0,36,IF(E10=1,36,IF(E10=2,36,IF(E10=3,36,IF(E10=4,36,IF(E10=5,24,0))))))+IF(F10=0,31,IF(F10=1,31,IF(F10=2,31,IF(F10=3,31,IF(F10=4,31,IF(F10=5,31,IF(F10=6,31,IF(F10=7,27,IF(F10=8,21,IF(F10=9,12,0))))))))))+IF(G10=0,31,IF(G10=1,31,IF(G10=2,31,IF(G10=3,31,IF(G10=4,31,IF(G10=5,31,IF(G10=6,31,IF(G10=7,27,IF(G10=8,21,IF(G10=9,12,0))))))))))+IF(H10=0,31,IF(H10=1,31,IF(H10=2,31,IF(H10=3,31,IF(H10=4,31,IF(H10=5,31,IF(H10=6,31,IF(H10=7,27,IF(H10=8,21,IF(H10=9,12,0)))))))))) -> 129 | P10: =IF(E10=0,30,IF(E10=1,30,IF(E10=2,30,IF(E10=3,18,0))))+IF(F10=0,22,IF(F10=1,22,IF(F10=2,22,IF(F10=3,19,IF(F10=4,15,IF(F10=5,9,0))))))+IF(G10=0,31,IF(G10=1,31,IF(G10=2,31,IF(G10=3,31,IF(G10=4,31,IF(G10=5,31,0))))))+IF(H10=0,22,IF(H10=1,22,IF(H10=2,22,IF(H10=3,19,IF(H10=4,15,IF(H10=5,9,0)))))) -> 105 | Q10: =IF(E10=0,18,IF(E10=1,15,0))+IF(F10=0,6,IF(F10=1,6,0))+IF(G10=0,6,IF(G10=1,6,0))+IF(H10=0,6,IF(H10=1,6,0)) -> 33 | R10: Призрачная оболочка | S10: =IF(F10=0,6,IF(F10=1,6,IF(F10=2,6,IF(F10=3,6,IF(F10=4,6,IF(F10=5,6,IF(F10=6,6,IF(F10=7,5,IF(F10=8,4,IF(F10=9,2,0))))))))))+IF(G10=0,6,IF(G10=1,6,IF(G10=2,6,IF(G10=3,6,IF(G10=4,6,IF(G10=5,6,IF(G10=6,6,IF(G10=7,5,IF(G10=8,4,IF(G10=9,2,0))))))))))+IF(H10=0,6,IF(H10=1,6,IF(H10=2,6,IF(H10=3,6,IF(H10=4,6,IF(H10=5,6,IF(H10=6,6,IF(H10=7,5,IF(H10=8,4,IF(H10=9,2,0)))))))))) -> 18 | T10: Вечный янтарь | U10: =IF(F10=10,0,1)+IF(G10=10,0,1)+IF(H10=10,0,1) -> 3 | V10: =IF(F10=0,38,IF(F10=1,38,IF(F10=2,38,IF(F10=3,38,IF(F10=4,38,IF(F10=5,38,IF(F10=6,38,IF(F10=7,34,IF(F10=8,28,IF(F10=9,16,0))))))))))+IF(G10=0,38,IF(G10=1,38,IF(G10=2,38,IF(G10=3,38,IF(G10=4,38,IF(G10=5,38,IF(G10=6,38,IF(G10=7,34,IF(G10=8,28,IF(G10=9,16,0))))))))))+IF(H10=0,38,IF(H10=1,38,IF(H10=2,38,IF(H10=3,38,IF(H10=4,38,IF(H10=5,38,IF(H10=6,38,IF(H10=7,34,IF(H10=8,28,IF(H10=9,16,0)))))))))) -> 114 | W10: =IF(F10=0,21,IF(F10=1,21,IF(F10=2,21,IF(F10=3,19,IF(F10=4,15,IF(F10=5,9,0))))))+IF(G10=0,21,IF(G10=1,21,IF(G10=2,21,IF(G10=3,19,IF(G10=4,15,IF(G10=5,21,0))))))+IF(H10=0,21,IF(H10=1,21,IF(H10=2,21,IF(H10=3,19,IF(H10=4,15,IF(H10=5,9,0)))))) -> 63 | X10: =IF(F10=0,3,IF(F10=1,3,0))+IF(G10=0,3,IF(G10=1,3,0))+IF(H10=0,3,IF(H10=1,3,0)) -> 9 | Y10: Бренность | Z10: =IF(E10=0,168,IF(E10=1,165,IF(E10=2,155,IF(E10=3,135,IF(E10=4,105,IF(E10=5,60,0)))))) -> 165 | AA10: Плод облачной травы | AB10: 1
A11: Куки Синобу | B11: 4 | C11: Инадзума | D11: Электро | E11: 3 | F11: 1 | G11: 1 | H11: 1 | I11: =IF(E11=6,0,6) -> 6 | J11: =IF(E11=0,9,IF(E11=1,9,IF(E11=2,9,IF(E11=3,9,IF(E11=4,6,0))))) -> 9 | K11: =IF(E11=0,9,IF(E11=1,9,IF(E11=2,6,0))) -> 0 | L11: =IF(E11=0,1,0) -> 0 | M11: =IF(E11=0,46,IF(E11=1,46,IF(E11=2,44,IF(E11=3,40,IF(E11=4,32,IF(E11=5,20,0)))))) -> 40 | N11: Рунический клык | O11: =IF(E11=0,36,IF(E11=1,36,IF(E11=2,36,IF(E11=3,36,IF(E11=4,36,IF(E11=5,24,0))))))+IF(F11=0,31,IF(F11=1,31,IF(F11=2,31,IF(F11=3,31,IF(F11=4,31,IF(F11=5,31,IF(F11=6,31,IF(F11=7,27,IF(F11=8,21,IF(F11=9,12,0))))))))))+IF(G11=0,31,IF(G11=1,31,IF(G11=2,31,IF(G11=3,31,IF(G11=4,31,IF(G11=5,31,IF(G11=6,31,IF(G11=7,27,IF(G11=8,21,IF(G11=9,12,0))))))))))+IF(H11=0,31,IF(H11=1,31,IF(H11=2,31,IF(H11=3,31,IF(H11=4,31,IF(H11=5,31,IF(H11=6,31,IF(H11=7,27,IF(H11=8,21,IF(H11=9,12,0)))))))))) -> 129 | P11: =IF(E11=0,30,IF(E11=1,30,IF(E11=2,30,IF(E11=3,18,0))))+IF(F11=0,22,IF(F11=1,22,IF(F11=2,22,IF(F11=3,19,IF(F11=4,15,IF(F11=5,9,0))))))+IF(G11=0,31,IF(G11=1,31,IF(G11=2,31,IF(G11=3,31,IF(G11=4,31,IF(G11=5,31,0))))))+IF(H11=0,22,IF(H11=1,22,IF(H11=2,22,IF(H11=3,19,IF(H11=4,15,IF(H11=5,9,0)))))) -> 93 | Q11: =IF(E11=0,18,IF(E11=1,15,0))+IF(F11=0,6,IF(F11=1,6,0))+IF(G11=0,6,IF(G11=1,6,0))+IF(H11=0,6,IF(H11=1,6,0)) -> 18 | R11: Призрачная оболочка | S11: =IF(F11=0,6,IF(F11=1,6,IF(F11=2,6,IF(F11=3,6,IF(F11=4,6,IF(F11=5,6,IF(F11=6,6,IF(F11=7,5,IF(F11=8,4,IF(F11=9,2,0))))))))))+IF(G11=0,6,IF(G11=1,6,IF(G11=2,6,IF(G11=3,6,IF(G11=4,6,IF(G11=5,6,IF(G11=6,6,IF(G11=7,5,IF(G11=8,4,IF(G11=9,2,0))))))))))+IF(H11=0,6,IF(H11=1,6,IF(H11=2,6,IF(H11=3,6,IF(H11=4,6,IF(H11=5,6,IF(H11=6,6,IF(H11=7,5,IF(H11=8,4,IF(H11=9,2,0)))))))))) -> 18 | T11: Слёзы очищения божества бедствий | U11: =IF(F11=10,0,1)+IF(G11=10,0,1)+IF(H11=10,0,1) -> 3 | V11: =IF(F11=0,38,IF(F11=1,38,IF(F11=2,38,IF(F11=3,38,IF(F11=4,38,IF(F11=5,38,IF(F11=6,38,IF(F11=7,34,IF(F11=8,28,IF(F11=9,16,0))))))))))+IF(G11=0,38,IF(G11=1,38,IF(G11=2,38,IF(G11=3,38,IF(G11=4,38,IF(G11=5,38,IF(G11=6,38,IF(G11=7,34,IF(G11=8,28,IF(G11=9,16,0))))))))))+IF(H11=0,38,IF(H11=1,38,IF(H11=2,38,IF(H11=3,38,IF(H11=4,38,IF(H11=5,38,IF(H11=6,38,IF(H11=7,34,IF(H11=8,28,IF(H11=9,16,0)))))))))) -> 114 | W11: =IF(F11=0,21,IF(F11=1,21,IF(F11=2,21,IF(F11=3,19,IF(F11=4,15,IF(F11=5,9,0))))))+IF(G11=0,21,IF(G11=1,21,IF(G11=2,21,IF(G11=3,19,IF(G11=4,15,IF(G11=5,21,0))))))+IF(H11=0,21,IF(H11=1,21,IF(H11=2,21,IF(H11=3,19,IF(H11=4,15,IF(H11=5,9,0)))))) -> 63 | X11: =IF(F11=0,3,IF(F11=1,3,0))+IF(G11=0,3,IF(G11=1,3,0))+IF(H11=0,3,IF(H11=1,3,0)) -> 9 | Y11: Изящество | Z11: =IF(E11=0,168,IF(E11=1,165,IF(E11=2,155,IF(E11=3,135,IF(E11=4,105,IF(E11=5,60,0)))))) -> 135 | AA11: Трава наку | AB11: 1
A12: Сара | B12: 4 | C12: Инадзума | D12: Электро | E12: 3 | F12: 2 | G12: 4 | H12: 4 | I12: =IF(E12=6,0,6) -> 6 | J12: =IF(E12=0,9,IF(E12=1,9,IF(E12=2,9,IF(E12=3,9,IF(E12=4,6,0))))) -> 9 | K12: =IF(E12=0,9,IF(E12=1,9,IF(E12=2,6,0))) -> 0 | L12: =IF(E12=0,1,0) -> 0 | M12: =IF(E12=0,46,IF(E12=1,46,IF(E12=2,44,IF(E12=3,40,IF(E12=4,32,IF(E12=5,20,0)))))) -> 40 | N12: Штормовой жемчуг | O12: =IF(E12=0,36,IF(E12=1,36,IF(E12=2,36,IF(E12=3,36,IF(E12=4,36,IF(E12=5,24,0))))))+IF(F12=0,31,IF(F12=1,31,IF(F12=2,31,IF(F12=3,31,IF(F12=4,31,IF(F12=5,31,IF(F12=6,31,IF(F12=7,27,IF(F12=8,21,IF(F12=9,12,0))))))))))+IF(G12=0,31,IF(G12=1,31,IF(G12=2,31,IF(G12=3,31,IF(G12=4,31,IF(G12=5,31,IF(G12=6,31,IF(G12=7,27,IF(G12=8,21,IF(G12=9,12,0))))))))))+IF(H12=0,31,IF(H12=1,31,IF(H12=2,31,IF(H12=3,31,IF(H12=4,31,IF(H12=5,31,IF(H12=6,31,IF(H12=7,27,IF(H12=8,21,IF(H12=9,12,0)))))))))) -> 129 | P12: =IF(E12=0,30,IF(E12=1,30,IF(E12=2,30,IF(E12=3,18,0))))+IF(F12=0,22,IF(F12=1,22,IF(F12=2,22,IF(F12=3,19,IF(F12=4,15,IF(F12=5,9,0))))))+IF(G12=0,31,IF(G12=1,31,IF(G12=2,31,IF(G12=3,31,IF(G12=4,31,IF(G12=5,31,0))))))+IF(H12=0,22,IF(H12=1,22,IF(H12=2,22,IF(H12=3,19,IF(H12=4,15,IF(H12=5,9,0)))))) -> 86 | Q12: =IF(E12=0,18,IF(E12=1,15,0))+IF(F12=0,6,IF(F12=1,6,0))+IF(G12=0,6,IF(G12=1,6,0))+IF(H12=0,6,IF(H12=1,6,0)) -> 0 | R12: Разбитая маска | S12: =IF(F12=0,6,IF(F12=1,6,IF(F12=2,6,IF(F12=3,6,IF(F12=4,6,IF(F12=5,6,IF(F12=6,6,IF(F12=7,5,IF(F12=8,4,IF(F12=9,2,0))))))))))+IF(G12=0,6,IF(G12=1,6,IF(G12=2,6,IF(G12=3,6,IF(G12=4,6,IF(G12=5,6,IF(G12=6,6,IF(G12=7,5,IF(G12=8,4,IF(G12=9,2,0))))))))))+IF(H12=0,6,IF(H12=1,6,IF(H12=2,6,IF(H12=3,6,IF(H12=4,6,IF(H12=5,6,IF(H12=6,6,IF(H12=7,5,IF(H12=8,4,IF(H12=9,2,0)))))))))) -> 18 | T12: Пепельное сердце | U12: =IF(F12=10,0,1)+IF(G12=10,0,1)+IF(H12=10,0,1) -> 3 | V12: =IF(F12=0,38,IF(F12=1,38,IF(F12=2,38,IF(F12=3,38,IF(F12=4,38,IF(F12=5,38,IF(F12=6,38,IF(F12=7,34,IF(F12=8,28,IF(F12=9,16,0))))))))))+IF(G12=0,38,IF(G12=1,38,IF(G12=2,38,IF(G12=3,38,IF(G12=4,38,IF(G12=5,38,IF(G12=6,38,IF(G12=7,34,IF(G12=8,28,IF(G12=9,16,0))))))))))+IF(H12=0,38,IF(H12=1,38,IF(H12=2,38,IF(H12=3,38,IF(H12=4,38,IF(H12=5,38,IF(H12=6,38,IF(H12=7,34,IF(H12=8,28,IF(H12=9,16,0)))))))))) -> 114 | W12: =IF(F12=0,21,IF(F12=1,21,IF(F12=2,21,IF(F12=3,19,IF(F12=4,15,IF(F12=5,9,0))))))+IF(G12=0,21,IF(G12=1,21,IF(G12=2,21,IF(G12=3,19,IF(G12=4,15,IF(G12=5,21,0))))))+IF(H12=0,21,IF(H12=1,21,IF(H12=2,21,IF(H12=3,19,IF(H12=4,15,IF(H12=5,9,0)))))) -> 51 | X12: =IF(F12=0,3,IF(F12=1,3,0))+IF(G12=0,3,IF(G12=1,3,0))+IF(H12=0,3,IF(H12=1,3,0)) -> 0 | Y12: Изящество | Z12: =IF(E12=0,168,IF(E12=1,165,IF(E12=2,155,IF(E12=3,135,IF(E12=4,105,IF(E12=5,60,0)))))) -> 135 | AA12: Кровоцвет
